[2024-04-29T17:49:58.202+0000] {processor.py:161} INFO - Started process (PID=10122) to work on /opt/airflow/dags/my_first_dag.py
[2024-04-29T17:49:58.202+0000] {processor.py:830} INFO - Processing file /opt/airflow/dags/my_first_dag.py for tasks to queue
[2024-04-29T17:49:58.203+0000] {logging_mixin.py:188} INFO - [2024-04-29T17:49:58.203+0000] {dagbag.py:540} INFO - Filling up the DagBag from /opt/airflow/dags/my_first_dag.py
[2024-04-29T17:49:58.207+0000] {logging_mixin.py:188} INFO - [2024-04-29T17:49:58.205+0000] {dagbag.py:350} ERROR - Failed to import: /opt/airflow/dags/my_first_dag.py
Traceback (most recent call last):
  File "/home/airflow/.local/lib/python3.8/site-packages/airflow/models/dagbag.py", line 346, in parse
    loader.exec_module(new_module)
  File "<frozen importlib._bootstrap_external>", line 839, in exec_module
  File "<frozen importlib._bootstrap_external>", line 976, in get_code
  File "<frozen importlib._bootstrap_external>", line 906, in source_to_code
  File "<frozen importlib._bootstrap>", line 219, in _call_with_frames_removed
  File "/opt/airflow/dags/my_first_dag.py", line 5
    f.
     ^
SyntaxError: invalid syntax
[2024-04-29T17:49:58.208+0000] {processor.py:842} WARNING - No viable dags retrieved from /opt/airflow/dags/my_first_dag.py
[2024-04-29T17:49:58.239+0000] {processor.py:183} INFO - Processing /opt/airflow/dags/my_first_dag.py took 0.041 seconds
[2024-04-29T17:50:00.326+0000] {processor.py:161} INFO - Started process (PID=10137) to work on /opt/airflow/dags/my_first_dag.py
[2024-04-29T17:50:00.327+0000] {processor.py:830} INFO - Processing file /opt/airflow/dags/my_first_dag.py for tasks to queue
[2024-04-29T17:50:00.327+0000] {logging_mixin.py:188} INFO - [2024-04-29T17:50:00.327+0000] {dagbag.py:540} INFO - Filling up the DagBag from /opt/airflow/dags/my_first_dag.py
[2024-04-29T17:50:00.331+0000] {logging_mixin.py:188} INFO - [2024-04-29T17:50:00.330+0000] {dagbag.py:350} ERROR - Failed to import: /opt/airflow/dags/my_first_dag.py
Traceback (most recent call last):
  File "/home/airflow/.local/lib/python3.8/site-packages/airflow/models/dagbag.py", line 346, in parse
    loader.exec_module(new_module)
  File "<frozen importlib._bootstrap_external>", line 843, in exec_module
  File "<frozen importlib._bootstrap>", line 219, in _call_with_frames_removed
  File "/opt/airflow/dags/my_first_dag.py", line 5, in <module>
    f._____
AttributeError: '_io.TextIOWrapper' object has no attribute '_____'
[2024-04-29T17:50:00.331+0000] {processor.py:842} WARNING - No viable dags retrieved from /opt/airflow/dags/my_first_dag.py
[2024-04-29T17:50:00.362+0000] {processor.py:183} INFO - Processing /opt/airflow/dags/my_first_dag.py took 0.039 seconds
[2024-04-29T17:50:02.530+0000] {processor.py:161} INFO - Started process (PID=10152) to work on /opt/airflow/dags/my_first_dag.py
[2024-04-29T17:50:02.532+0000] {processor.py:830} INFO - Processing file /opt/airflow/dags/my_first_dag.py for tasks to queue
[2024-04-29T17:50:02.533+0000] {logging_mixin.py:188} INFO - [2024-04-29T17:50:02.532+0000] {dagbag.py:540} INFO - Filling up the DagBag from /opt/airflow/dags/my_first_dag.py
[2024-04-29T17:50:02.537+0000] {logging_mixin.py:188} INFO - [2024-04-29T17:50:02.536+0000] {dagbag.py:350} ERROR - Failed to import: /opt/airflow/dags/my_first_dag.py
Traceback (most recent call last):
  File "/home/airflow/.local/lib/python3.8/site-packages/airflow/models/dagbag.py", line 346, in parse
    loader.exec_module(new_module)
  File "<frozen importlib._bootstrap_external>", line 843, in exec_module
  File "<frozen importlib._bootstrap>", line 219, in _call_with_frames_removed
  File "/opt/airflow/dags/my_first_dag.py", line 5, in <module>
    f._____
AttributeError: '_io.TextIOWrapper' object has no attribute '_____'
[2024-04-29T17:50:02.538+0000] {processor.py:842} WARNING - No viable dags retrieved from /opt/airflow/dags/my_first_dag.py
[2024-04-29T17:50:02.565+0000] {processor.py:183} INFO - Processing /opt/airflow/dags/my_first_dag.py took 0.039 seconds
[2024-04-29T17:50:06.287+0000] {processor.py:161} INFO - Started process (PID=10212) to work on /opt/airflow/dags/my_first_dag.py
[2024-04-29T17:50:06.287+0000] {processor.py:830} INFO - Processing file /opt/airflow/dags/my_first_dag.py for tasks to queue
[2024-04-29T17:50:06.288+0000] {logging_mixin.py:188} INFO - [2024-04-29T17:50:06.288+0000] {dagbag.py:540} INFO - Filling up the DagBag from /opt/airflow/dags/my_first_dag.py
[2024-04-29T17:50:06.291+0000] {logging_mixin.py:188} INFO - [2024-04-29T17:50:06.290+0000] {dagbag.py:350} ERROR - Failed to import: /opt/airflow/dags/my_first_dag.py
Traceback (most recent call last):
  File "/home/airflow/.local/lib/python3.8/site-packages/airflow/models/dagbag.py", line 346, in parse
    loader.exec_module(new_module)
  File "<frozen importlib._bootstrap_external>", line 843, in exec_module
  File "<frozen importlib._bootstrap>", line 219, in _call_with_frames_removed
  File "/opt/airflow/dags/my_first_dag.py", line 5, in <module>
    f._____
AttributeError: '_io.TextIOWrapper' object has no attribute '_____'
[2024-04-29T17:50:06.291+0000] {processor.py:842} WARNING - No viable dags retrieved from /opt/airflow/dags/my_first_dag.py
[2024-04-29T17:50:06.313+0000] {processor.py:183} INFO - Processing /opt/airflow/dags/my_first_dag.py took 0.029 seconds
[2024-04-29T17:50:11.345+0000] {processor.py:161} INFO - Started process (PID=10217) to work on /opt/airflow/dags/my_first_dag.py
[2024-04-29T17:50:11.346+0000] {processor.py:830} INFO - Processing file /opt/airflow/dags/my_first_dag.py for tasks to queue
[2024-04-29T17:50:11.347+0000] {logging_mixin.py:188} INFO - [2024-04-29T17:50:11.346+0000] {dagbag.py:540} INFO - Filling up the DagBag from /opt/airflow/dags/my_first_dag.py
[2024-04-29T17:50:11.350+0000] {logging_mixin.py:188} INFO - [2024-04-29T17:50:11.349+0000] {dagbag.py:350} ERROR - Failed to import: /opt/airflow/dags/my_first_dag.py
Traceback (most recent call last):
  File "/home/airflow/.local/lib/python3.8/site-packages/airflow/models/dagbag.py", line 346, in parse
    loader.exec_module(new_module)
  File "<frozen importlib._bootstrap_external>", line 843, in exec_module
  File "<frozen importlib._bootstrap>", line 219, in _call_with_frames_removed
  File "/opt/airflow/dags/my_first_dag.py", line 5, in <module>
    f._____
AttributeError: '_io.TextIOWrapper' object has no attribute '_____'
[2024-04-29T17:50:11.350+0000] {processor.py:842} WARNING - No viable dags retrieved from /opt/airflow/dags/my_first_dag.py
[2024-04-29T17:50:11.371+0000] {processor.py:183} INFO - Processing /opt/airflow/dags/my_first_dag.py took 0.028 seconds
[2024-04-29T17:50:16.934+0000] {processor.py:161} INFO - Started process (PID=10239) to work on /opt/airflow/dags/my_first_dag.py
[2024-04-29T17:50:16.935+0000] {processor.py:830} INFO - Processing file /opt/airflow/dags/my_first_dag.py for tasks to queue
[2024-04-29T17:50:16.936+0000] {logging_mixin.py:188} INFO - [2024-04-29T17:50:16.936+0000] {dagbag.py:540} INFO - Filling up the DagBag from /opt/airflow/dags/my_first_dag.py
[2024-04-29T17:50:16.939+0000] {logging_mixin.py:188} INFO - [2024-04-29T17:50:16.938+0000] {dagbag.py:350} ERROR - Failed to import: /opt/airflow/dags/my_first_dag.py
Traceback (most recent call last):
  File "/home/airflow/.local/lib/python3.8/site-packages/airflow/models/dagbag.py", line 346, in parse
    loader.exec_module(new_module)
  File "<frozen importlib._bootstrap_external>", line 843, in exec_module
  File "<frozen importlib._bootstrap>", line 219, in _call_with_frames_removed
  File "/opt/airflow/dags/my_first_dag.py", line 5, in <module>
    f._____
AttributeError: '_io.TextIOWrapper' object has no attribute '_____'
[2024-04-29T17:50:16.939+0000] {processor.py:842} WARNING - No viable dags retrieved from /opt/airflow/dags/my_first_dag.py
[2024-04-29T17:50:16.960+0000] {processor.py:183} INFO - Processing /opt/airflow/dags/my_first_dag.py took 0.029 seconds
[2024-04-29T17:50:19.475+0000] {processor.py:161} INFO - Started process (PID=10274) to work on /opt/airflow/dags/my_first_dag.py
[2024-04-29T17:50:19.475+0000] {processor.py:830} INFO - Processing file /opt/airflow/dags/my_first_dag.py for tasks to queue
[2024-04-29T17:50:19.476+0000] {logging_mixin.py:188} INFO - [2024-04-29T17:50:19.476+0000] {dagbag.py:540} INFO - Filling up the DagBag from /opt/airflow/dags/my_first_dag.py
[2024-04-29T17:50:19.481+0000] {logging_mixin.py:188} INFO - [2024-04-29T17:50:19.480+0000] {dagbag.py:350} ERROR - Failed to import: /opt/airflow/dags/my_first_dag.py
Traceback (most recent call last):
  File "/home/airflow/.local/lib/python3.8/site-packages/airflow/models/dagbag.py", line 346, in parse
    loader.exec_module(new_module)
  File "<frozen importlib._bootstrap_external>", line 843, in exec_module
  File "<frozen importlib._bootstrap>", line 219, in _call_with_frames_removed
  File "/opt/airflow/dags/my_first_dag.py", line 5, in <module>
    f._____
AttributeError: '_io.TextIOWrapper' object has no attribute '_____'
[2024-04-29T17:50:19.481+0000] {processor.py:842} WARNING - No viable dags retrieved from /opt/airflow/dags/my_first_dag.py
[2024-04-29T17:50:19.510+0000] {processor.py:183} INFO - Processing /opt/airflow/dags/my_first_dag.py took 0.039 seconds
[2024-04-29T17:50:25.526+0000] {processor.py:161} INFO - Started process (PID=10349) to work on /opt/airflow/dags/my_first_dag.py
[2024-04-29T17:50:25.527+0000] {processor.py:830} INFO - Processing file /opt/airflow/dags/my_first_dag.py for tasks to queue
[2024-04-29T17:50:25.528+0000] {logging_mixin.py:188} INFO - [2024-04-29T17:50:25.528+0000] {dagbag.py:540} INFO - Filling up the DagBag from /opt/airflow/dags/my_first_dag.py
[2024-04-29T17:50:25.533+0000] {logging_mixin.py:188} INFO - [2024-04-29T17:50:25.532+0000] {dagbag.py:350} ERROR - Failed to import: /opt/airflow/dags/my_first_dag.py
Traceback (most recent call last):
  File "/home/airflow/.local/lib/python3.8/site-packages/airflow/models/dagbag.py", line 346, in parse
    loader.exec_module(new_module)
  File "<frozen importlib._bootstrap_external>", line 843, in exec_module
  File "<frozen importlib._bootstrap>", line 219, in _call_with_frames_removed
  File "/opt/airflow/dags/my_first_dag.py", line 8, in <module>
    f = open("")
FileNotFoundError: [Errno 2] No such file or directory: ''
[2024-04-29T17:50:25.534+0000] {processor.py:842} WARNING - No viable dags retrieved from /opt/airflow/dags/my_first_dag.py
[2024-04-29T17:50:25.570+0000] {processor.py:183} INFO - Processing /opt/airflow/dags/my_first_dag.py took 0.047 seconds
[2024-04-29T17:50:30.463+0000] {processor.py:161} INFO - Started process (PID=10419) to work on /opt/airflow/dags/my_first_dag.py
[2024-04-29T17:50:30.464+0000] {processor.py:830} INFO - Processing file /opt/airflow/dags/my_first_dag.py for tasks to queue
[2024-04-29T17:50:30.465+0000] {logging_mixin.py:188} INFO - [2024-04-29T17:50:30.464+0000] {dagbag.py:540} INFO - Filling up the DagBag from /opt/airflow/dags/my_first_dag.py
[2024-04-29T17:50:30.469+0000] {logging_mixin.py:188} INFO - [2024-04-29T17:50:30.468+0000] {dagbag.py:350} ERROR - Failed to import: /opt/airflow/dags/my_first_dag.py
Traceback (most recent call last):
  File "/home/airflow/.local/lib/python3.8/site-packages/airflow/models/dagbag.py", line 346, in parse
    loader.exec_module(new_module)
  File "<frozen importlib._bootstrap_external>", line 843, in exec_module
  File "<frozen importlib._bootstrap>", line 219, in _call_with_frames_removed
  File "/opt/airflow/dags/my_first_dag.py", line 8, in <module>
    f = open("")
FileNotFoundError: [Errno 2] No such file or directory: ''
[2024-04-29T17:50:30.469+0000] {processor.py:842} WARNING - No viable dags retrieved from /opt/airflow/dags/my_first_dag.py
[2024-04-29T17:50:30.498+0000] {processor.py:183} INFO - Processing /opt/airflow/dags/my_first_dag.py took 0.040 seconds
[2024-04-29T17:50:31.649+0000] {processor.py:161} INFO - Started process (PID=10434) to work on /opt/airflow/dags/my_first_dag.py
[2024-04-29T17:50:31.650+0000] {processor.py:830} INFO - Processing file /opt/airflow/dags/my_first_dag.py for tasks to queue
[2024-04-29T17:50:31.651+0000] {logging_mixin.py:188} INFO - [2024-04-29T17:50:31.650+0000] {dagbag.py:540} INFO - Filling up the DagBag from /opt/airflow/dags/my_first_dag.py
[2024-04-29T17:50:31.654+0000] {logging_mixin.py:188} INFO - [2024-04-29T17:50:31.653+0000] {dagbag.py:350} ERROR - Failed to import: /opt/airflow/dags/my_first_dag.py
Traceback (most recent call last):
  File "/home/airflow/.local/lib/python3.8/site-packages/airflow/models/dagbag.py", line 346, in parse
    loader.exec_module(new_module)
  File "<frozen importlib._bootstrap_external>", line 843, in exec_module
  File "<frozen importlib._bootstrap>", line 219, in _call_with_frames_removed
  File "/opt/airflow/dags/my_first_dag.py", line 8, in <module>
    f = open("")
FileNotFoundError: [Errno 2] No such file or directory: ''
[2024-04-29T17:50:31.654+0000] {processor.py:842} WARNING - No viable dags retrieved from /opt/airflow/dags/my_first_dag.py
[2024-04-29T17:50:31.678+0000] {processor.py:183} INFO - Processing /opt/airflow/dags/my_first_dag.py took 0.032 seconds
[2024-04-29T17:50:35.390+0000] {processor.py:161} INFO - Started process (PID=10494) to work on /opt/airflow/dags/my_first_dag.py
[2024-04-29T17:50:35.391+0000] {processor.py:830} INFO - Processing file /opt/airflow/dags/my_first_dag.py for tasks to queue
[2024-04-29T17:50:35.392+0000] {logging_mixin.py:188} INFO - [2024-04-29T17:50:35.391+0000] {dagbag.py:540} INFO - Filling up the DagBag from /opt/airflow/dags/my_first_dag.py
[2024-04-29T17:50:35.394+0000] {logging_mixin.py:188} INFO - [2024-04-29T17:50:35.394+0000] {dagbag.py:350} ERROR - Failed to import: /opt/airflow/dags/my_first_dag.py
Traceback (most recent call last):
  File "/home/airflow/.local/lib/python3.8/site-packages/airflow/models/dagbag.py", line 346, in parse
    loader.exec_module(new_module)
  File "<frozen importlib._bootstrap_external>", line 843, in exec_module
  File "<frozen importlib._bootstrap>", line 219, in _call_with_frames_removed
  File "/opt/airflow/dags/my_first_dag.py", line 8, in <module>
    f = open("")
FileNotFoundError: [Errno 2] No such file or directory: ''
[2024-04-29T17:50:35.395+0000] {processor.py:842} WARNING - No viable dags retrieved from /opt/airflow/dags/my_first_dag.py
[2024-04-29T17:50:35.418+0000] {processor.py:183} INFO - Processing /opt/airflow/dags/my_first_dag.py took 0.030 seconds
[2024-04-29T17:50:40.415+0000] {processor.py:161} INFO - Started process (PID=10499) to work on /opt/airflow/dags/my_first_dag.py
[2024-04-29T17:50:40.416+0000] {processor.py:830} INFO - Processing file /opt/airflow/dags/my_first_dag.py for tasks to queue
[2024-04-29T17:50:40.417+0000] {logging_mixin.py:188} INFO - [2024-04-29T17:50:40.417+0000] {dagbag.py:540} INFO - Filling up the DagBag from /opt/airflow/dags/my_first_dag.py
[2024-04-29T17:50:40.419+0000] {logging_mixin.py:188} INFO - [2024-04-29T17:50:40.419+0000] {dagbag.py:350} ERROR - Failed to import: /opt/airflow/dags/my_first_dag.py
Traceback (most recent call last):
  File "/home/airflow/.local/lib/python3.8/site-packages/airflow/models/dagbag.py", line 346, in parse
    loader.exec_module(new_module)
  File "<frozen importlib._bootstrap_external>", line 843, in exec_module
  File "<frozen importlib._bootstrap>", line 219, in _call_with_frames_removed
  File "/opt/airflow/dags/my_first_dag.py", line 8, in <module>
    f = open("")
FileNotFoundError: [Errno 2] No such file or directory: ''
[2024-04-29T17:50:40.420+0000] {processor.py:842} WARNING - No viable dags retrieved from /opt/airflow/dags/my_first_dag.py
[2024-04-29T17:50:40.443+0000] {processor.py:183} INFO - Processing /opt/airflow/dags/my_first_dag.py took 0.030 seconds
[2024-04-29T17:50:48.857+0000] {processor.py:161} INFO - Started process (PID=10529) to work on /opt/airflow/dags/my_first_dag.py
[2024-04-29T17:50:48.858+0000] {processor.py:830} INFO - Processing file /opt/airflow/dags/my_first_dag.py for tasks to queue
[2024-04-29T17:50:48.859+0000] {logging_mixin.py:188} INFO - [2024-04-29T17:50:48.859+0000] {dagbag.py:540} INFO - Filling up the DagBag from /opt/airflow/dags/my_first_dag.py
[2024-04-29T17:50:48.863+0000] {logging_mixin.py:188} INFO - [2024-04-29T17:50:48.862+0000] {dagbag.py:350} ERROR - Failed to import: /opt/airflow/dags/my_first_dag.py
Traceback (most recent call last):
  File "/home/airflow/.local/lib/python3.8/site-packages/airflow/models/dagbag.py", line 346, in parse
    loader.exec_module(new_module)
  File "<frozen importlib._bootstrap_external>", line 843, in exec_module
  File "<frozen importlib._bootstrap>", line 219, in _call_with_frames_removed
  File "/opt/airflow/dags/my_first_dag.py", line 9, in <module>
    f = open("")
FileNotFoundError: [Errno 2] No such file or directory: ''
[2024-04-29T17:50:48.864+0000] {processor.py:842} WARNING - No viable dags retrieved from /opt/airflow/dags/my_first_dag.py
[2024-04-29T17:50:48.888+0000] {processor.py:183} INFO - Processing /opt/airflow/dags/my_first_dag.py took 0.034 seconds
[2024-04-29T17:50:51.605+0000] {processor.py:161} INFO - Started process (PID=10576) to work on /opt/airflow/dags/my_first_dag.py
[2024-04-29T17:50:51.607+0000] {processor.py:830} INFO - Processing file /opt/airflow/dags/my_first_dag.py for tasks to queue
[2024-04-29T17:50:51.608+0000] {logging_mixin.py:188} INFO - [2024-04-29T17:50:51.607+0000] {dagbag.py:540} INFO - Filling up the DagBag from /opt/airflow/dags/my_first_dag.py
[2024-04-29T17:50:51.612+0000] {logging_mixin.py:188} INFO - [2024-04-29T17:50:51.611+0000] {dagbag.py:350} ERROR - Failed to import: /opt/airflow/dags/my_first_dag.py
Traceback (most recent call last):
  File "/home/airflow/.local/lib/python3.8/site-packages/airflow/models/dagbag.py", line 346, in parse
    loader.exec_module(new_module)
  File "<frozen importlib._bootstrap_external>", line 843, in exec_module
  File "<frozen importlib._bootstrap>", line 219, in _call_with_frames_removed
  File "/opt/airflow/dags/my_first_dag.py", line 9, in <module>
    f = open("")
FileNotFoundError: [Errno 2] No such file or directory: ''
[2024-04-29T17:50:51.613+0000] {processor.py:842} WARNING - No viable dags retrieved from /opt/airflow/dags/my_first_dag.py
[2024-04-29T17:50:51.643+0000] {processor.py:183} INFO - Processing /opt/airflow/dags/my_first_dag.py took 0.040 seconds
[2024-04-29T17:50:53.394+0000] {processor.py:161} INFO - Started process (PID=10626) to work on /opt/airflow/dags/my_first_dag.py
[2024-04-29T17:50:53.395+0000] {processor.py:830} INFO - Processing file /opt/airflow/dags/my_first_dag.py for tasks to queue
[2024-04-29T17:50:53.395+0000] {logging_mixin.py:188} INFO - [2024-04-29T17:50:53.395+0000] {dagbag.py:540} INFO - Filling up the DagBag from /opt/airflow/dags/my_first_dag.py
[2024-04-29T17:50:53.397+0000] {processor.py:842} WARNING - No viable dags retrieved from /opt/airflow/dags/my_first_dag.py
[2024-04-29T17:50:53.419+0000] {processor.py:183} INFO - Processing /opt/airflow/dags/my_first_dag.py took 0.028 seconds
[2024-04-29T17:50:58.078+0000] {processor.py:161} INFO - Started process (PID=10676) to work on /opt/airflow/dags/my_first_dag.py
[2024-04-29T17:50:58.079+0000] {processor.py:830} INFO - Processing file /opt/airflow/dags/my_first_dag.py for tasks to queue
[2024-04-29T17:50:58.080+0000] {logging_mixin.py:188} INFO - [2024-04-29T17:50:58.079+0000] {dagbag.py:540} INFO - Filling up the DagBag from /opt/airflow/dags/my_first_dag.py
[2024-04-29T17:50:58.083+0000] {processor.py:842} WARNING - No viable dags retrieved from /opt/airflow/dags/my_first_dag.py
[2024-04-29T17:50:58.122+0000] {processor.py:183} INFO - Processing /opt/airflow/dags/my_first_dag.py took 0.048 seconds
[2024-04-29T17:51:02.539+0000] {processor.py:161} INFO - Started process (PID=10716) to work on /opt/airflow/dags/my_first_dag.py
[2024-04-29T17:51:02.540+0000] {processor.py:830} INFO - Processing file /opt/airflow/dags/my_first_dag.py for tasks to queue
[2024-04-29T17:51:02.541+0000] {logging_mixin.py:188} INFO - [2024-04-29T17:51:02.540+0000] {dagbag.py:540} INFO - Filling up the DagBag from /opt/airflow/dags/my_first_dag.py
[2024-04-29T17:51:02.543+0000] {processor.py:842} WARNING - No viable dags retrieved from /opt/airflow/dags/my_first_dag.py
[2024-04-29T17:51:02.553+0000] {processor.py:183} INFO - Processing /opt/airflow/dags/my_first_dag.py took 0.017 seconds
[2024-04-29T17:51:10.410+0000] {processor.py:161} INFO - Started process (PID=10776) to work on /opt/airflow/dags/my_first_dag.py
[2024-04-29T17:51:10.410+0000] {processor.py:830} INFO - Processing file /opt/airflow/dags/my_first_dag.py for tasks to queue
[2024-04-29T17:51:10.411+0000] {logging_mixin.py:188} INFO - [2024-04-29T17:51:10.411+0000] {dagbag.py:540} INFO - Filling up the DagBag from /opt/airflow/dags/my_first_dag.py
[2024-04-29T17:51:10.413+0000] {logging_mixin.py:188} INFO - [2024-04-29T17:51:10.413+0000] {dagbag.py:350} ERROR - Failed to import: /opt/airflow/dags/my_first_dag.py
Traceback (most recent call last):
  File "/home/airflow/.local/lib/python3.8/site-packages/airflow/models/dagbag.py", line 346, in parse
    loader.exec_module(new_module)
  File "<frozen importlib._bootstrap_external>", line 839, in exec_module
  File "<frozen importlib._bootstrap_external>", line 976, in get_code
  File "<frozen importlib._bootstrap_external>", line 906, in source_to_code
  File "<frozen importlib._bootstrap>", line 219, in _call_with_frames_removed
  File "/opt/airflow/dags/my_first_dag.py", line 12
    with DAG()
             ^
SyntaxError: invalid syntax
[2024-04-29T17:51:10.414+0000] {processor.py:842} WARNING - No viable dags retrieved from /opt/airflow/dags/my_first_dag.py
[2024-04-29T17:51:10.441+0000] {processor.py:183} INFO - Processing /opt/airflow/dags/my_first_dag.py took 0.034 seconds
[2024-04-29T17:51:16.477+0000] {processor.py:161} INFO - Started process (PID=10781) to work on /opt/airflow/dags/my_first_dag.py
[2024-04-29T17:51:16.479+0000] {processor.py:830} INFO - Processing file /opt/airflow/dags/my_first_dag.py for tasks to queue
[2024-04-29T17:51:16.480+0000] {logging_mixin.py:188} INFO - [2024-04-29T17:51:16.479+0000] {dagbag.py:540} INFO - Filling up the DagBag from /opt/airflow/dags/my_first_dag.py
[2024-04-29T17:51:16.486+0000] {logging_mixin.py:188} INFO - [2024-04-29T17:51:16.485+0000] {dagbag.py:350} ERROR - Failed to import: /opt/airflow/dags/my_first_dag.py
Traceback (most recent call last):
  File "/home/airflow/.local/lib/python3.8/site-packages/airflow/models/dagbag.py", line 346, in parse
    loader.exec_module(new_module)
  File "<frozen importlib._bootstrap_external>", line 839, in exec_module
  File "<frozen importlib._bootstrap_external>", line 976, in get_code
  File "<frozen importlib._bootstrap_external>", line 906, in source_to_code
  File "<frozen importlib._bootstrap>", line 219, in _call_with_frames_removed
  File "/opt/airflow/dags/my_first_dag.py", line 12
    with DAG():
              ^
SyntaxError: unexpected EOF while parsing
[2024-04-29T17:51:16.486+0000] {processor.py:842} WARNING - No viable dags retrieved from /opt/airflow/dags/my_first_dag.py
[2024-04-29T17:51:16.509+0000] {processor.py:183} INFO - Processing /opt/airflow/dags/my_first_dag.py took 0.037 seconds
[2024-04-29T17:51:20.112+0000] {processor.py:161} INFO - Started process (PID=10814) to work on /opt/airflow/dags/my_first_dag.py
[2024-04-29T17:51:20.113+0000] {processor.py:830} INFO - Processing file /opt/airflow/dags/my_first_dag.py for tasks to queue
[2024-04-29T17:51:20.114+0000] {logging_mixin.py:188} INFO - [2024-04-29T17:51:20.114+0000] {dagbag.py:540} INFO - Filling up the DagBag from /opt/airflow/dags/my_first_dag.py
[2024-04-29T17:51:20.117+0000] {logging_mixin.py:188} INFO - [2024-04-29T17:51:20.116+0000] {dagbag.py:350} ERROR - Failed to import: /opt/airflow/dags/my_first_dag.py
Traceback (most recent call last):
  File "/home/airflow/.local/lib/python3.8/site-packages/airflow/models/dagbag.py", line 346, in parse
    loader.exec_module(new_module)
  File "<frozen importlib._bootstrap_external>", line 839, in exec_module
  File "<frozen importlib._bootstrap_external>", line 976, in get_code
  File "<frozen importlib._bootstrap_external>", line 906, in source_to_code
  File "<frozen importlib._bootstrap>", line 219, in _call_with_frames_removed
  File "/opt/airflow/dags/my_first_dag.py", line 15
    ):
     ^
SyntaxError: unexpected EOF while parsing
[2024-04-29T17:51:20.117+0000] {processor.py:842} WARNING - No viable dags retrieved from /opt/airflow/dags/my_first_dag.py
[2024-04-29T17:51:20.147+0000] {processor.py:183} INFO - Processing /opt/airflow/dags/my_first_dag.py took 0.038 seconds
[2024-04-29T17:51:25.182+0000] {processor.py:161} INFO - Started process (PID=10904) to work on /opt/airflow/dags/my_first_dag.py
[2024-04-29T17:51:25.183+0000] {processor.py:830} INFO - Processing file /opt/airflow/dags/my_first_dag.py for tasks to queue
[2024-04-29T17:51:25.184+0000] {logging_mixin.py:188} INFO - [2024-04-29T17:51:25.184+0000] {dagbag.py:540} INFO - Filling up the DagBag from /opt/airflow/dags/my_first_dag.py
[2024-04-29T17:51:25.186+0000] {logging_mixin.py:188} INFO - [2024-04-29T17:51:25.185+0000] {dagbag.py:350} ERROR - Failed to import: /opt/airflow/dags/my_first_dag.py
Traceback (most recent call last):
  File "/home/airflow/.local/lib/python3.8/site-packages/airflow/models/dagbag.py", line 346, in parse
    loader.exec_module(new_module)
  File "<frozen importlib._bootstrap_external>", line 839, in exec_module
  File "<frozen importlib._bootstrap_external>", line 976, in get_code
  File "<frozen importlib._bootstrap_external>", line 906, in source_to_code
  File "<frozen importlib._bootstrap>", line 219, in _call_with_frames_removed
  File "/opt/airflow/dags/my_first_dag.py", line 16
    ):
     ^
SyntaxError: unexpected EOF while parsing
[2024-04-29T17:51:25.186+0000] {processor.py:842} WARNING - No viable dags retrieved from /opt/airflow/dags/my_first_dag.py
[2024-04-29T17:51:25.208+0000] {processor.py:183} INFO - Processing /opt/airflow/dags/my_first_dag.py took 0.028 seconds
[2024-04-29T17:51:27.763+0000] {processor.py:161} INFO - Started process (PID=10952) to work on /opt/airflow/dags/my_first_dag.py
[2024-04-29T17:51:27.764+0000] {processor.py:830} INFO - Processing file /opt/airflow/dags/my_first_dag.py for tasks to queue
[2024-04-29T17:51:27.766+0000] {logging_mixin.py:188} INFO - [2024-04-29T17:51:27.765+0000] {dagbag.py:540} INFO - Filling up the DagBag from /opt/airflow/dags/my_first_dag.py
[2024-04-29T17:51:27.769+0000] {logging_mixin.py:188} INFO - [2024-04-29T17:51:27.768+0000] {dagbag.py:350} ERROR - Failed to import: /opt/airflow/dags/my_first_dag.py
Traceback (most recent call last):
  File "/home/airflow/.local/lib/python3.8/site-packages/airflow/models/dagbag.py", line 346, in parse
    loader.exec_module(new_module)
  File "<frozen importlib._bootstrap_external>", line 839, in exec_module
  File "<frozen importlib._bootstrap_external>", line 976, in get_code
  File "<frozen importlib._bootstrap_external>", line 906, in source_to_code
  File "<frozen importlib._bootstrap>", line 219, in _call_with_frames_removed
  File "/opt/airflow/dags/my_first_dag.py", line 15
    ):
     ^
SyntaxError: unexpected EOF while parsing
[2024-04-29T17:51:27.769+0000] {processor.py:842} WARNING - No viable dags retrieved from /opt/airflow/dags/my_first_dag.py
[2024-04-29T17:51:27.798+0000] {processor.py:183} INFO - Processing /opt/airflow/dags/my_first_dag.py took 0.038 seconds
[2024-04-29T17:51:34.296+0000] {processor.py:161} INFO - Started process (PID=10994) to work on /opt/airflow/dags/my_first_dag.py
[2024-04-29T17:51:34.297+0000] {processor.py:830} INFO - Processing file /opt/airflow/dags/my_first_dag.py for tasks to queue
[2024-04-29T17:51:34.298+0000] {logging_mixin.py:188} INFO - [2024-04-29T17:51:34.297+0000] {dagbag.py:540} INFO - Filling up the DagBag from /opt/airflow/dags/my_first_dag.py
[2024-04-29T17:51:34.300+0000] {logging_mixin.py:188} INFO - [2024-04-29T17:51:34.299+0000] {dagbag.py:350} ERROR - Failed to import: /opt/airflow/dags/my_first_dag.py
Traceback (most recent call last):
  File "/home/airflow/.local/lib/python3.8/site-packages/airflow/models/dagbag.py", line 346, in parse
    loader.exec_module(new_module)
  File "<frozen importlib._bootstrap_external>", line 839, in exec_module
  File "<frozen importlib._bootstrap_external>", line 976, in get_code
  File "<frozen importlib._bootstrap_external>", line 906, in source_to_code
  File "<frozen importlib._bootstrap>", line 219, in _call_with_frames_removed
  File "/opt/airflow/dags/my_first_dag.py", line 16
    ):
     ^
SyntaxError: unexpected EOF while parsing
[2024-04-29T17:51:34.300+0000] {processor.py:842} WARNING - No viable dags retrieved from /opt/airflow/dags/my_first_dag.py
[2024-04-29T17:51:34.321+0000] {processor.py:183} INFO - Processing /opt/airflow/dags/my_first_dag.py took 0.028 seconds
[2024-04-29T17:51:42.162+0000] {processor.py:161} INFO - Started process (PID=11054) to work on /opt/airflow/dags/my_first_dag.py
[2024-04-29T17:51:42.163+0000] {processor.py:830} INFO - Processing file /opt/airflow/dags/my_first_dag.py for tasks to queue
[2024-04-29T17:51:42.164+0000] {logging_mixin.py:188} INFO - [2024-04-29T17:51:42.164+0000] {dagbag.py:540} INFO - Filling up the DagBag from /opt/airflow/dags/my_first_dag.py
[2024-04-29T17:51:42.166+0000] {logging_mixin.py:188} INFO - [2024-04-29T17:51:42.165+0000] {dagbag.py:350} ERROR - Failed to import: /opt/airflow/dags/my_first_dag.py
Traceback (most recent call last):
  File "/home/airflow/.local/lib/python3.8/site-packages/airflow/models/dagbag.py", line 346, in parse
    loader.exec_module(new_module)
  File "<frozen importlib._bootstrap_external>", line 839, in exec_module
  File "<frozen importlib._bootstrap_external>", line 976, in get_code
  File "<frozen importlib._bootstrap_external>", line 906, in source_to_code
  File "<frozen importlib._bootstrap>", line 219, in _call_with_frames_removed
  File "/opt/airflow/dags/my_first_dag.py", line 16
    ):
     ^
SyntaxError: unexpected EOF while parsing
[2024-04-29T17:51:42.166+0000] {processor.py:842} WARNING - No viable dags retrieved from /opt/airflow/dags/my_first_dag.py
[2024-04-29T17:51:42.191+0000] {processor.py:183} INFO - Processing /opt/airflow/dags/my_first_dag.py took 0.031 seconds
[2024-04-29T17:51:46.227+0000] {processor.py:161} INFO - Started process (PID=11059) to work on /opt/airflow/dags/my_first_dag.py
[2024-04-29T17:51:46.228+0000] {processor.py:830} INFO - Processing file /opt/airflow/dags/my_first_dag.py for tasks to queue
[2024-04-29T17:51:46.229+0000] {logging_mixin.py:188} INFO - [2024-04-29T17:51:46.229+0000] {dagbag.py:540} INFO - Filling up the DagBag from /opt/airflow/dags/my_first_dag.py
[2024-04-29T17:51:46.231+0000] {logging_mixin.py:188} INFO - [2024-04-29T17:51:46.230+0000] {dagbag.py:350} ERROR - Failed to import: /opt/airflow/dags/my_first_dag.py
Traceback (most recent call last):
  File "/home/airflow/.local/lib/python3.8/site-packages/airflow/models/dagbag.py", line 346, in parse
    loader.exec_module(new_module)
  File "<frozen importlib._bootstrap_external>", line 839, in exec_module
  File "<frozen importlib._bootstrap_external>", line 976, in get_code
  File "<frozen importlib._bootstrap_external>", line 906, in source_to_code
  File "<frozen importlib._bootstrap>", line 219, in _call_with_frames_removed
  File "/opt/airflow/dags/my_first_dag.py", line 16
    ):
     ^
SyntaxError: unexpected EOF while parsing
[2024-04-29T17:51:46.231+0000] {processor.py:842} WARNING - No viable dags retrieved from /opt/airflow/dags/my_first_dag.py
[2024-04-29T17:51:46.252+0000] {processor.py:183} INFO - Processing /opt/airflow/dags/my_first_dag.py took 0.028 seconds
[2024-04-29T17:51:49.957+0000] {processor.py:161} INFO - Started process (PID=11090) to work on /opt/airflow/dags/my_first_dag.py
[2024-04-29T17:51:49.958+0000] {processor.py:830} INFO - Processing file /opt/airflow/dags/my_first_dag.py for tasks to queue
[2024-04-29T17:51:49.959+0000] {logging_mixin.py:188} INFO - [2024-04-29T17:51:49.958+0000] {dagbag.py:540} INFO - Filling up the DagBag from /opt/airflow/dags/my_first_dag.py
[2024-04-29T17:51:49.961+0000] {logging_mixin.py:188} INFO - [2024-04-29T17:51:49.960+0000] {dagbag.py:350} ERROR - Failed to import: /opt/airflow/dags/my_first_dag.py
Traceback (most recent call last):
  File "/home/airflow/.local/lib/python3.8/site-packages/airflow/models/dagbag.py", line 346, in parse
    loader.exec_module(new_module)
  File "<frozen importlib._bootstrap_external>", line 839, in exec_module
  File "<frozen importlib._bootstrap_external>", line 976, in get_code
  File "<frozen importlib._bootstrap_external>", line 906, in source_to_code
  File "<frozen importlib._bootstrap>", line 219, in _call_with_frames_removed
  File "/opt/airflow/dags/my_first_dag.py", line 16
    ):
     ^
SyntaxError: unexpected EOF while parsing
[2024-04-29T17:51:49.961+0000] {processor.py:842} WARNING - No viable dags retrieved from /opt/airflow/dags/my_first_dag.py
[2024-04-29T17:51:49.982+0000] {processor.py:183} INFO - Processing /opt/airflow/dags/my_first_dag.py took 0.028 seconds
[2024-04-29T17:51:55.955+0000] {processor.py:161} INFO - Started process (PID=11180) to work on /opt/airflow/dags/my_first_dag.py
[2024-04-29T17:51:55.956+0000] {processor.py:830} INFO - Processing file /opt/airflow/dags/my_first_dag.py for tasks to queue
[2024-04-29T17:51:55.957+0000] {logging_mixin.py:188} INFO - [2024-04-29T17:51:55.957+0000] {dagbag.py:540} INFO - Filling up the DagBag from /opt/airflow/dags/my_first_dag.py
[2024-04-29T17:51:55.959+0000] {logging_mixin.py:188} INFO - [2024-04-29T17:51:55.958+0000] {dagbag.py:350} ERROR - Failed to import: /opt/airflow/dags/my_first_dag.py
Traceback (most recent call last):
  File "/home/airflow/.local/lib/python3.8/site-packages/airflow/models/dagbag.py", line 346, in parse
    loader.exec_module(new_module)
  File "<frozen importlib._bootstrap_external>", line 839, in exec_module
  File "<frozen importlib._bootstrap_external>", line 976, in get_code
  File "<frozen importlib._bootstrap_external>", line 906, in source_to_code
  File "<frozen importlib._bootstrap>", line 219, in _call_with_frames_removed
  File "/opt/airflow/dags/my_first_dag.py", line 16
    ):
     ^
SyntaxError: unexpected EOF while parsing
[2024-04-29T17:51:55.959+0000] {processor.py:842} WARNING - No viable dags retrieved from /opt/airflow/dags/my_first_dag.py
[2024-04-29T17:51:55.981+0000] {processor.py:183} INFO - Processing /opt/airflow/dags/my_first_dag.py took 0.028 seconds
[2024-04-29T17:52:01.808+0000] {processor.py:161} INFO - Started process (PID=11255) to work on /opt/airflow/dags/my_first_dag.py
[2024-04-29T17:52:01.809+0000] {processor.py:830} INFO - Processing file /opt/airflow/dags/my_first_dag.py for tasks to queue
[2024-04-29T17:52:01.810+0000] {logging_mixin.py:188} INFO - [2024-04-29T17:52:01.809+0000] {dagbag.py:540} INFO - Filling up the DagBag from /opt/airflow/dags/my_first_dag.py
[2024-04-29T17:52:01.812+0000] {logging_mixin.py:188} INFO - [2024-04-29T17:52:01.811+0000] {dagbag.py:350} ERROR - Failed to import: /opt/airflow/dags/my_first_dag.py
Traceback (most recent call last):
  File "/home/airflow/.local/lib/python3.8/site-packages/airflow/models/dagbag.py", line 346, in parse
    loader.exec_module(new_module)
  File "<frozen importlib._bootstrap_external>", line 839, in exec_module
  File "<frozen importlib._bootstrap_external>", line 976, in get_code
  File "<frozen importlib._bootstrap_external>", line 906, in source_to_code
  File "<frozen importlib._bootstrap>", line 219, in _call_with_frames_removed
  File "/opt/airflow/dags/my_first_dag.py", line 16
    ):
     ^
SyntaxError: unexpected EOF while parsing
[2024-04-29T17:52:01.812+0000] {processor.py:842} WARNING - No viable dags retrieved from /opt/airflow/dags/my_first_dag.py
[2024-04-29T17:52:01.834+0000] {processor.py:183} INFO - Processing /opt/airflow/dags/my_first_dag.py took 0.028 seconds
[2024-04-29T17:52:18.833+0000] {processor.py:161} INFO - Started process (PID=11331) to work on /opt/airflow/dags/my_first_dag.py
[2024-04-29T17:52:18.834+0000] {processor.py:830} INFO - Processing file /opt/airflow/dags/my_first_dag.py for tasks to queue
[2024-04-29T17:52:18.835+0000] {logging_mixin.py:188} INFO - [2024-04-29T17:52:18.835+0000] {dagbag.py:540} INFO - Filling up the DagBag from /opt/airflow/dags/my_first_dag.py
[2024-04-29T17:52:18.837+0000] {logging_mixin.py:188} INFO - [2024-04-29T17:52:18.837+0000] {dagbag.py:350} ERROR - Failed to import: /opt/airflow/dags/my_first_dag.py
Traceback (most recent call last):
  File "/home/airflow/.local/lib/python3.8/site-packages/airflow/models/dagbag.py", line 346, in parse
    loader.exec_module(new_module)
  File "<frozen importlib._bootstrap_external>", line 839, in exec_module
  File "<frozen importlib._bootstrap_external>", line 976, in get_code
  File "<frozen importlib._bootstrap_external>", line 906, in source_to_code
  File "<frozen importlib._bootstrap>", line 219, in _call_with_frames_removed
  File "/opt/airflow/dags/my_first_dag.py", line 17
    ):
     ^
SyntaxError: unexpected EOF while parsing
[2024-04-29T17:52:18.838+0000] {processor.py:842} WARNING - No viable dags retrieved from /opt/airflow/dags/my_first_dag.py
[2024-04-29T17:52:18.860+0000] {processor.py:183} INFO - Processing /opt/airflow/dags/my_first_dag.py took 0.029 seconds
[2024-04-29T17:52:21.532+0000] {processor.py:161} INFO - Started process (PID=11375) to work on /opt/airflow/dags/my_first_dag.py
[2024-04-29T17:52:21.539+0000] {processor.py:830} INFO - Processing file /opt/airflow/dags/my_first_dag.py for tasks to queue
[2024-04-29T17:52:21.540+0000] {logging_mixin.py:188} INFO - [2024-04-29T17:52:21.540+0000] {dagbag.py:540} INFO - Filling up the DagBag from /opt/airflow/dags/my_first_dag.py
[2024-04-29T17:52:21.548+0000] {logging_mixin.py:188} INFO - [2024-04-29T17:52:21.547+0000] {dagbag.py:350} ERROR - Failed to import: /opt/airflow/dags/my_first_dag.py
Traceback (most recent call last):
  File "/home/airflow/.local/lib/python3.8/site-packages/airflow/models/dagbag.py", line 346, in parse
    loader.exec_module(new_module)
  File "<frozen importlib._bootstrap_external>", line 839, in exec_module
  File "<frozen importlib._bootstrap_external>", line 976, in get_code
  File "<frozen importlib._bootstrap_external>", line 906, in source_to_code
  File "<frozen importlib._bootstrap>", line 219, in _call_with_frames_removed
  File "/opt/airflow/dags/my_first_dag.py", line 18
    ):
     ^
SyntaxError: unexpected EOF while parsing
[2024-04-29T17:52:21.551+0000] {processor.py:842} WARNING - No viable dags retrieved from /opt/airflow/dags/my_first_dag.py
[2024-04-29T17:52:21.592+0000] {processor.py:183} INFO - Processing /opt/airflow/dags/my_first_dag.py took 0.066 seconds
[2024-04-29T17:52:23.957+0000] {processor.py:161} INFO - Started process (PID=11402) to work on /opt/airflow/dags/my_first_dag.py
[2024-04-29T17:52:23.958+0000] {processor.py:830} INFO - Processing file /opt/airflow/dags/my_first_dag.py for tasks to queue
[2024-04-29T17:52:23.959+0000] {logging_mixin.py:188} INFO - [2024-04-29T17:52:23.959+0000] {dagbag.py:540} INFO - Filling up the DagBag from /opt/airflow/dags/my_first_dag.py
[2024-04-29T17:52:23.962+0000] {logging_mixin.py:188} INFO - [2024-04-29T17:52:23.961+0000] {dagbag.py:350} ERROR - Failed to import: /opt/airflow/dags/my_first_dag.py
Traceback (most recent call last):
  File "/home/airflow/.local/lib/python3.8/site-packages/airflow/models/dagbag.py", line 346, in parse
    loader.exec_module(new_module)
  File "<frozen importlib._bootstrap_external>", line 839, in exec_module
  File "<frozen importlib._bootstrap_external>", line 976, in get_code
  File "<frozen importlib._bootstrap_external>", line 906, in source_to_code
  File "<frozen importlib._bootstrap>", line 219, in _call_with_frames_removed
  File "/opt/airflow/dags/my_first_dag.py", line 18
    ):
     ^
SyntaxError: unexpected EOF while parsing
[2024-04-29T17:52:23.971+0000] {processor.py:842} WARNING - No viable dags retrieved from /opt/airflow/dags/my_first_dag.py
[2024-04-29T17:52:24.017+0000] {processor.py:183} INFO - Processing /opt/airflow/dags/my_first_dag.py took 0.065 seconds
[2024-04-29T17:52:25.121+0000] {processor.py:161} INFO - Started process (PID=11417) to work on /opt/airflow/dags/my_first_dag.py
[2024-04-29T17:52:25.122+0000] {processor.py:830} INFO - Processing file /opt/airflow/dags/my_first_dag.py for tasks to queue
[2024-04-29T17:52:25.122+0000] {logging_mixin.py:188} INFO - [2024-04-29T17:52:25.122+0000] {dagbag.py:540} INFO - Filling up the DagBag from /opt/airflow/dags/my_first_dag.py
[2024-04-29T17:52:25.125+0000] {logging_mixin.py:188} INFO - [2024-04-29T17:52:25.124+0000] {dagbag.py:350} ERROR - Failed to import: /opt/airflow/dags/my_first_dag.py
Traceback (most recent call last):
  File "/home/airflow/.local/lib/python3.8/site-packages/airflow/models/dagbag.py", line 346, in parse
    loader.exec_module(new_module)
  File "<frozen importlib._bootstrap_external>", line 839, in exec_module
  File "<frozen importlib._bootstrap_external>", line 976, in get_code
  File "<frozen importlib._bootstrap_external>", line 906, in source_to_code
  File "<frozen importlib._bootstrap>", line 219, in _call_with_frames_removed
  File "/opt/airflow/dags/my_first_dag.py", line 18
    ):
     ^
SyntaxError: unexpected EOF while parsing
[2024-04-29T17:52:25.125+0000] {processor.py:842} WARNING - No viable dags retrieved from /opt/airflow/dags/my_first_dag.py
[2024-04-29T17:52:25.153+0000] {processor.py:183} INFO - Processing /opt/airflow/dags/my_first_dag.py took 0.036 seconds
[2024-04-29T17:52:27.639+0000] {processor.py:161} INFO - Started process (PID=11457) to work on /opt/airflow/dags/my_first_dag.py
[2024-04-29T17:52:27.640+0000] {processor.py:830} INFO - Processing file /opt/airflow/dags/my_first_dag.py for tasks to queue
[2024-04-29T17:52:27.642+0000] {logging_mixin.py:188} INFO - [2024-04-29T17:52:27.641+0000] {dagbag.py:540} INFO - Filling up the DagBag from /opt/airflow/dags/my_first_dag.py
[2024-04-29T17:52:27.644+0000] {logging_mixin.py:188} INFO - [2024-04-29T17:52:27.644+0000] {dagbag.py:350} ERROR - Failed to import: /opt/airflow/dags/my_first_dag.py
Traceback (most recent call last):
  File "/home/airflow/.local/lib/python3.8/site-packages/airflow/models/dagbag.py", line 346, in parse
    loader.exec_module(new_module)
  File "<frozen importlib._bootstrap_external>", line 839, in exec_module
  File "<frozen importlib._bootstrap_external>", line 976, in get_code
  File "<frozen importlib._bootstrap_external>", line 906, in source_to_code
  File "<frozen importlib._bootstrap>", line 219, in _call_with_frames_removed
  File "/opt/airflow/dags/my_first_dag.py", line 18
    ):
     ^
SyntaxError: unexpected EOF while parsing
[2024-04-29T17:52:27.645+0000] {processor.py:842} WARNING - No viable dags retrieved from /opt/airflow/dags/my_first_dag.py
[2024-04-29T17:52:27.671+0000] {processor.py:183} INFO - Processing /opt/airflow/dags/my_first_dag.py took 0.036 seconds
[2024-04-29T17:52:36.765+0000] {processor.py:161} INFO - Started process (PID=11542) to work on /opt/airflow/dags/my_first_dag.py
[2024-04-29T17:52:36.767+0000] {processor.py:830} INFO - Processing file /opt/airflow/dags/my_first_dag.py for tasks to queue
[2024-04-29T17:52:36.768+0000] {logging_mixin.py:188} INFO - [2024-04-29T17:52:36.768+0000] {dagbag.py:540} INFO - Filling up the DagBag from /opt/airflow/dags/my_first_dag.py
[2024-04-29T17:52:36.771+0000] {logging_mixin.py:188} INFO - [2024-04-29T17:52:36.770+0000] {dagbag.py:350} ERROR - Failed to import: /opt/airflow/dags/my_first_dag.py
Traceback (most recent call last):
  File "/home/airflow/.local/lib/python3.8/site-packages/airflow/models/dagbag.py", line 346, in parse
    loader.exec_module(new_module)
  File "<frozen importlib._bootstrap_external>", line 839, in exec_module
  File "<frozen importlib._bootstrap_external>", line 976, in get_code
  File "<frozen importlib._bootstrap_external>", line 906, in source_to_code
  File "<frozen importlib._bootstrap>", line 219, in _call_with_frames_removed
  File "/opt/airflow/dags/my_first_dag.py", line 18
    ):
     ^
SyntaxError: unexpected EOF while parsing
[2024-04-29T17:52:36.771+0000] {processor.py:842} WARNING - No viable dags retrieved from /opt/airflow/dags/my_first_dag.py
[2024-04-29T17:52:36.802+0000] {processor.py:183} INFO - Processing /opt/airflow/dags/my_first_dag.py took 0.040 seconds
[2024-04-29T17:52:38.708+0000] {processor.py:161} INFO - Started process (PID=11602) to work on /opt/airflow/dags/my_first_dag.py
[2024-04-29T17:52:38.709+0000] {processor.py:830} INFO - Processing file /opt/airflow/dags/my_first_dag.py for tasks to queue
[2024-04-29T17:52:38.710+0000] {logging_mixin.py:188} INFO - [2024-04-29T17:52:38.710+0000] {dagbag.py:540} INFO - Filling up the DagBag from /opt/airflow/dags/my_first_dag.py
[2024-04-29T17:52:38.713+0000] {logging_mixin.py:188} INFO - [2024-04-29T17:52:38.712+0000] {dagbag.py:350} ERROR - Failed to import: /opt/airflow/dags/my_first_dag.py
Traceback (most recent call last):
  File "/home/airflow/.local/lib/python3.8/site-packages/airflow/models/dagbag.py", line 346, in parse
    loader.exec_module(new_module)
  File "<frozen importlib._bootstrap_external>", line 839, in exec_module
  File "<frozen importlib._bootstrap_external>", line 976, in get_code
  File "<frozen importlib._bootstrap_external>", line 906, in source_to_code
  File "<frozen importlib._bootstrap>", line 219, in _call_with_frames_removed
  File "/opt/airflow/dags/my_first_dag.py", line 18
    ):
     ^
SyntaxError: unexpected EOF while parsing
[2024-04-29T17:52:38.713+0000] {processor.py:842} WARNING - No viable dags retrieved from /opt/airflow/dags/my_first_dag.py
[2024-04-29T17:52:38.738+0000] {processor.py:183} INFO - Processing /opt/airflow/dags/my_first_dag.py took 0.033 seconds
[2024-04-29T17:52:39.727+0000] {processor.py:161} INFO - Started process (PID=11607) to work on /opt/airflow/dags/my_first_dag.py
[2024-04-29T17:52:39.728+0000] {processor.py:830} INFO - Processing file /opt/airflow/dags/my_first_dag.py for tasks to queue
[2024-04-29T17:52:39.728+0000] {logging_mixin.py:188} INFO - [2024-04-29T17:52:39.728+0000] {dagbag.py:540} INFO - Filling up the DagBag from /opt/airflow/dags/my_first_dag.py
[2024-04-29T17:52:39.730+0000] {logging_mixin.py:188} INFO - [2024-04-29T17:52:39.730+0000] {dagbag.py:350} ERROR - Failed to import: /opt/airflow/dags/my_first_dag.py
Traceback (most recent call last):
  File "/home/airflow/.local/lib/python3.8/site-packages/airflow/models/dagbag.py", line 346, in parse
    loader.exec_module(new_module)
  File "<frozen importlib._bootstrap_external>", line 839, in exec_module
  File "<frozen importlib._bootstrap_external>", line 976, in get_code
  File "<frozen importlib._bootstrap_external>", line 906, in source_to_code
  File "<frozen importlib._bootstrap>", line 219, in _call_with_frames_removed
  File "/opt/airflow/dags/my_first_dag.py", line 18
    ):
     ^
SyntaxError: unexpected EOF while parsing
[2024-04-29T17:52:39.731+0000] {processor.py:842} WARNING - No viable dags retrieved from /opt/airflow/dags/my_first_dag.py
[2024-04-29T17:52:39.752+0000] {processor.py:183} INFO - Processing /opt/airflow/dags/my_first_dag.py took 0.028 seconds
[2024-04-29T17:52:42.783+0000] {processor.py:161} INFO - Started process (PID=11612) to work on /opt/airflow/dags/my_first_dag.py
[2024-04-29T17:52:42.784+0000] {processor.py:830} INFO - Processing file /opt/airflow/dags/my_first_dag.py for tasks to queue
[2024-04-29T17:52:42.784+0000] {logging_mixin.py:188} INFO - [2024-04-29T17:52:42.784+0000] {dagbag.py:540} INFO - Filling up the DagBag from /opt/airflow/dags/my_first_dag.py
[2024-04-29T17:52:42.786+0000] {logging_mixin.py:188} INFO - [2024-04-29T17:52:42.786+0000] {dagbag.py:350} ERROR - Failed to import: /opt/airflow/dags/my_first_dag.py
Traceback (most recent call last):
  File "/home/airflow/.local/lib/python3.8/site-packages/airflow/models/dagbag.py", line 346, in parse
    loader.exec_module(new_module)
  File "<frozen importlib._bootstrap_external>", line 839, in exec_module
  File "<frozen importlib._bootstrap_external>", line 976, in get_code
  File "<frozen importlib._bootstrap_external>", line 906, in source_to_code
  File "<frozen importlib._bootstrap>", line 219, in _call_with_frames_removed
  File "/opt/airflow/dags/my_first_dag.py", line 19
    ):
     ^
SyntaxError: unexpected EOF while parsing
[2024-04-29T17:52:42.787+0000] {processor.py:842} WARNING - No viable dags retrieved from /opt/airflow/dags/my_first_dag.py
[2024-04-29T17:52:42.808+0000] {processor.py:183} INFO - Processing /opt/airflow/dags/my_first_dag.py took 0.029 seconds
[2024-04-29T17:52:48.820+0000] {processor.py:161} INFO - Started process (PID=11623) to work on /opt/airflow/dags/my_first_dag.py
[2024-04-29T17:52:48.821+0000] {processor.py:830} INFO - Processing file /opt/airflow/dags/my_first_dag.py for tasks to queue
[2024-04-29T17:52:48.822+0000] {logging_mixin.py:188} INFO - [2024-04-29T17:52:48.822+0000] {dagbag.py:540} INFO - Filling up the DagBag from /opt/airflow/dags/my_first_dag.py
[2024-04-29T17:52:48.825+0000] {logging_mixin.py:188} INFO - [2024-04-29T17:52:48.824+0000] {dagbag.py:350} ERROR - Failed to import: /opt/airflow/dags/my_first_dag.py
Traceback (most recent call last):
  File "/home/airflow/.local/lib/python3.8/site-packages/airflow/models/dagbag.py", line 346, in parse
    loader.exec_module(new_module)
  File "<frozen importlib._bootstrap_external>", line 839, in exec_module
  File "<frozen importlib._bootstrap_external>", line 976, in get_code
  File "<frozen importlib._bootstrap_external>", line 906, in source_to_code
  File "<frozen importlib._bootstrap>", line 219, in _call_with_frames_removed
  File "/opt/airflow/dags/my_first_dag.py", line 17
    start_date=,
               ^
SyntaxError: invalid syntax
[2024-04-29T17:52:48.826+0000] {processor.py:842} WARNING - No viable dags retrieved from /opt/airflow/dags/my_first_dag.py
[2024-04-29T17:52:48.850+0000] {processor.py:183} INFO - Processing /opt/airflow/dags/my_first_dag.py took 0.034 seconds
[2024-04-29T17:53:01.740+0000] {processor.py:161} INFO - Started process (PID=11794) to work on /opt/airflow/dags/my_first_dag.py
[2024-04-29T17:53:01.740+0000] {processor.py:830} INFO - Processing file /opt/airflow/dags/my_first_dag.py for tasks to queue
[2024-04-29T17:53:01.741+0000] {logging_mixin.py:188} INFO - [2024-04-29T17:53:01.741+0000] {dagbag.py:540} INFO - Filling up the DagBag from /opt/airflow/dags/my_first_dag.py
[2024-04-29T17:53:01.744+0000] {logging_mixin.py:188} INFO - [2024-04-29T17:53:01.743+0000] {dagbag.py:350} ERROR - Failed to import: /opt/airflow/dags/my_first_dag.py
Traceback (most recent call last):
  File "/home/airflow/.local/lib/python3.8/site-packages/airflow/models/dagbag.py", line 346, in parse
    loader.exec_module(new_module)
  File "<frozen importlib._bootstrap_external>", line 839, in exec_module
  File "<frozen importlib._bootstrap_external>", line 976, in get_code
  File "<frozen importlib._bootstrap_external>", line 906, in source_to_code
  File "<frozen importlib._bootstrap>", line 219, in _call_with_frames_removed
  File "/opt/airflow/dags/my_first_dag.py", line 17
    start_date=,
               ^
SyntaxError: invalid syntax
[2024-04-29T17:53:01.744+0000] {processor.py:842} WARNING - No viable dags retrieved from /opt/airflow/dags/my_first_dag.py
[2024-04-29T17:53:01.772+0000] {processor.py:183} INFO - Processing /opt/airflow/dags/my_first_dag.py took 0.036 seconds
[2024-04-29T17:53:08.958+0000] {processor.py:161} INFO - Started process (PID=11874) to work on /opt/airflow/dags/my_first_dag.py
[2024-04-29T17:53:08.959+0000] {processor.py:830} INFO - Processing file /opt/airflow/dags/my_first_dag.py for tasks to queue
[2024-04-29T17:53:08.960+0000] {logging_mixin.py:188} INFO - [2024-04-29T17:53:08.959+0000] {dagbag.py:540} INFO - Filling up the DagBag from /opt/airflow/dags/my_first_dag.py
[2024-04-29T17:53:08.962+0000] {logging_mixin.py:188} INFO - [2024-04-29T17:53:08.961+0000] {dagbag.py:350} ERROR - Failed to import: /opt/airflow/dags/my_first_dag.py
Traceback (most recent call last):
  File "/home/airflow/.local/lib/python3.8/site-packages/airflow/models/dagbag.py", line 346, in parse
    loader.exec_module(new_module)
  File "<frozen importlib._bootstrap_external>", line 839, in exec_module
  File "<frozen importlib._bootstrap_external>", line 976, in get_code
  File "<frozen importlib._bootstrap_external>", line 906, in source_to_code
  File "<frozen importlib._bootstrap>", line 219, in _call_with_frames_removed
  File "/opt/airflow/dags/my_first_dag.py", line 17
    start_date=,
               ^
SyntaxError: invalid syntax
[2024-04-29T17:53:08.962+0000] {processor.py:842} WARNING - No viable dags retrieved from /opt/airflow/dags/my_first_dag.py
[2024-04-29T17:53:08.984+0000] {processor.py:183} INFO - Processing /opt/airflow/dags/my_first_dag.py took 0.028 seconds
[2024-04-29T17:53:20.015+0000] {processor.py:161} INFO - Started process (PID=11885) to work on /opt/airflow/dags/my_first_dag.py
[2024-04-29T17:53:20.016+0000] {processor.py:830} INFO - Processing file /opt/airflow/dags/my_first_dag.py for tasks to queue
[2024-04-29T17:53:20.017+0000] {logging_mixin.py:188} INFO - [2024-04-29T17:53:20.017+0000] {dagbag.py:540} INFO - Filling up the DagBag from /opt/airflow/dags/my_first_dag.py
[2024-04-29T17:53:20.020+0000] {logging_mixin.py:188} INFO - [2024-04-29T17:53:20.019+0000] {dagbag.py:350} ERROR - Failed to import: /opt/airflow/dags/my_first_dag.py
Traceback (most recent call last):
  File "/home/airflow/.local/lib/python3.8/site-packages/airflow/models/dagbag.py", line 346, in parse
    loader.exec_module(new_module)
  File "<frozen importlib._bootstrap_external>", line 839, in exec_module
  File "<frozen importlib._bootstrap_external>", line 976, in get_code
  File "<frozen importlib._bootstrap_external>", line 906, in source_to_code
  File "<frozen importlib._bootstrap>", line 219, in _call_with_frames_removed
  File "/opt/airflow/dags/my_first_dag.py", line 17
    start_date=,
               ^
SyntaxError: invalid syntax
[2024-04-29T17:53:20.020+0000] {processor.py:842} WARNING - No viable dags retrieved from /opt/airflow/dags/my_first_dag.py
[2024-04-29T17:53:20.043+0000] {processor.py:183} INFO - Processing /opt/airflow/dags/my_first_dag.py took 0.031 seconds
[2024-04-29T17:53:25.912+0000] {processor.py:161} INFO - Started process (PID=11961) to work on /opt/airflow/dags/my_first_dag.py
[2024-04-29T17:53:25.913+0000] {processor.py:830} INFO - Processing file /opt/airflow/dags/my_first_dag.py for tasks to queue
[2024-04-29T17:53:25.914+0000] {logging_mixin.py:188} INFO - [2024-04-29T17:53:25.914+0000] {dagbag.py:540} INFO - Filling up the DagBag from /opt/airflow/dags/my_first_dag.py
[2024-04-29T17:53:25.917+0000] {logging_mixin.py:188} INFO - [2024-04-29T17:53:25.916+0000] {dagbag.py:350} ERROR - Failed to import: /opt/airflow/dags/my_first_dag.py
Traceback (most recent call last):
  File "/home/airflow/.local/lib/python3.8/site-packages/airflow/models/dagbag.py", line 346, in parse
    loader.exec_module(new_module)
  File "<frozen importlib._bootstrap_external>", line 839, in exec_module
  File "<frozen importlib._bootstrap_external>", line 976, in get_code
  File "<frozen importlib._bootstrap_external>", line 906, in source_to_code
  File "<frozen importlib._bootstrap>", line 219, in _call_with_frames_removed
  File "/opt/airflow/dags/my_first_dag.py", line 17
    start_date=,
               ^
SyntaxError: invalid syntax
[2024-04-29T17:53:25.917+0000] {processor.py:842} WARNING - No viable dags retrieved from /opt/airflow/dags/my_first_dag.py
[2024-04-29T17:53:25.944+0000] {processor.py:183} INFO - Processing /opt/airflow/dags/my_first_dag.py took 0.035 seconds
[2024-04-29T17:53:33.358+0000] {processor.py:161} INFO - Started process (PID=12071) to work on /opt/airflow/dags/my_first_dag.py
[2024-04-29T17:53:33.359+0000] {processor.py:830} INFO - Processing file /opt/airflow/dags/my_first_dag.py for tasks to queue
[2024-04-29T17:53:33.360+0000] {logging_mixin.py:188} INFO - [2024-04-29T17:53:33.360+0000] {dagbag.py:540} INFO - Filling up the DagBag from /opt/airflow/dags/my_first_dag.py
[2024-04-29T17:53:33.364+0000] {logging_mixin.py:188} INFO - [2024-04-29T17:53:33.363+0000] {dagbag.py:350} ERROR - Failed to import: /opt/airflow/dags/my_first_dag.py
Traceback (most recent call last):
  File "/home/airflow/.local/lib/python3.8/site-packages/airflow/models/dagbag.py", line 346, in parse
    loader.exec_module(new_module)
  File "<frozen importlib._bootstrap_external>", line 839, in exec_module
  File "<frozen importlib._bootstrap_external>", line 976, in get_code
  File "<frozen importlib._bootstrap_external>", line 906, in source_to_code
  File "<frozen importlib._bootstrap>", line 219, in _call_with_frames_removed
  File "/opt/airflow/dags/my_first_dag.py", line 17
    start_date=,
               ^
SyntaxError: invalid syntax
[2024-04-29T17:53:33.365+0000] {processor.py:842} WARNING - No viable dags retrieved from /opt/airflow/dags/my_first_dag.py
[2024-04-29T17:53:33.393+0000] {processor.py:183} INFO - Processing /opt/airflow/dags/my_first_dag.py took 0.040 seconds
[2024-04-29T17:53:42.645+0000] {processor.py:161} INFO - Started process (PID=12141) to work on /opt/airflow/dags/my_first_dag.py
[2024-04-29T17:53:42.646+0000] {processor.py:830} INFO - Processing file /opt/airflow/dags/my_first_dag.py for tasks to queue
[2024-04-29T17:53:42.647+0000] {logging_mixin.py:188} INFO - [2024-04-29T17:53:42.647+0000] {dagbag.py:540} INFO - Filling up the DagBag from /opt/airflow/dags/my_first_dag.py
[2024-04-29T17:53:42.649+0000] {logging_mixin.py:188} INFO - [2024-04-29T17:53:42.649+0000] {dagbag.py:350} ERROR - Failed to import: /opt/airflow/dags/my_first_dag.py
Traceback (most recent call last):
  File "/home/airflow/.local/lib/python3.8/site-packages/airflow/models/dagbag.py", line 346, in parse
    loader.exec_module(new_module)
  File "<frozen importlib._bootstrap_external>", line 839, in exec_module
  File "<frozen importlib._bootstrap_external>", line 976, in get_code
  File "<frozen importlib._bootstrap_external>", line 906, in source_to_code
  File "<frozen importlib._bootstrap>", line 219, in _call_with_frames_removed
  File "/opt/airflow/dags/my_first_dag.py", line 18
    start_date=,
               ^
SyntaxError: invalid syntax
[2024-04-29T17:53:42.650+0000] {processor.py:842} WARNING - No viable dags retrieved from /opt/airflow/dags/my_first_dag.py
[2024-04-29T17:53:42.672+0000] {processor.py:183} INFO - Processing /opt/airflow/dags/my_first_dag.py took 0.029 seconds
[2024-04-29T17:53:56.732+0000] {processor.py:161} INFO - Started process (PID=12223) to work on /opt/airflow/dags/my_first_dag.py
[2024-04-29T17:53:56.733+0000] {processor.py:830} INFO - Processing file /opt/airflow/dags/my_first_dag.py for tasks to queue
[2024-04-29T17:53:56.734+0000] {logging_mixin.py:188} INFO - [2024-04-29T17:53:56.734+0000] {dagbag.py:540} INFO - Filling up the DagBag from /opt/airflow/dags/my_first_dag.py
[2024-04-29T17:53:56.737+0000] {logging_mixin.py:188} INFO - [2024-04-29T17:53:56.736+0000] {dagbag.py:350} ERROR - Failed to import: /opt/airflow/dags/my_first_dag.py
Traceback (most recent call last):
  File "/home/airflow/.local/lib/python3.8/site-packages/airflow/models/dagbag.py", line 346, in parse
    loader.exec_module(new_module)
  File "<frozen importlib._bootstrap_external>", line 839, in exec_module
  File "<frozen importlib._bootstrap_external>", line 976, in get_code
  File "<frozen importlib._bootstrap_external>", line 906, in source_to_code
  File "<frozen importlib._bootstrap>", line 219, in _call_with_frames_removed
  File "/opt/airflow/dags/my_first_dag.py", line 18
    start_date=,
               ^
SyntaxError: invalid syntax
[2024-04-29T17:53:56.737+0000] {processor.py:842} WARNING - No viable dags retrieved from /opt/airflow/dags/my_first_dag.py
[2024-04-29T17:53:56.764+0000] {processor.py:183} INFO - Processing /opt/airflow/dags/my_first_dag.py took 0.035 seconds
[2024-04-29T17:54:06.240+0000] {processor.py:161} INFO - Started process (PID=12343) to work on /opt/airflow/dags/my_first_dag.py
[2024-04-29T17:54:06.241+0000] {processor.py:830} INFO - Processing file /opt/airflow/dags/my_first_dag.py for tasks to queue
[2024-04-29T17:54:06.242+0000] {logging_mixin.py:188} INFO - [2024-04-29T17:54:06.241+0000] {dagbag.py:540} INFO - Filling up the DagBag from /opt/airflow/dags/my_first_dag.py
[2024-04-29T17:54:06.244+0000] {logging_mixin.py:188} INFO - [2024-04-29T17:54:06.243+0000] {dagbag.py:350} ERROR - Failed to import: /opt/airflow/dags/my_first_dag.py
Traceback (most recent call last):
  File "/home/airflow/.local/lib/python3.8/site-packages/airflow/models/dagbag.py", line 346, in parse
    loader.exec_module(new_module)
  File "<frozen importlib._bootstrap_external>", line 839, in exec_module
  File "<frozen importlib._bootstrap_external>", line 976, in get_code
  File "<frozen importlib._bootstrap_external>", line 906, in source_to_code
  File "<frozen importlib._bootstrap>", line 219, in _call_with_frames_removed
  File "/opt/airflow/dags/my_first_dag.py", line 19
    start_date=,
               ^
SyntaxError: invalid syntax
[2024-04-29T17:54:06.244+0000] {processor.py:842} WARNING - No viable dags retrieved from /opt/airflow/dags/my_first_dag.py
[2024-04-29T17:54:06.270+0000] {processor.py:183} INFO - Processing /opt/airflow/dags/my_first_dag.py took 0.033 seconds
[2024-04-29T17:54:08.273+0000] {processor.py:161} INFO - Started process (PID=12348) to work on /opt/airflow/dags/my_first_dag.py
[2024-04-29T17:54:08.274+0000] {processor.py:830} INFO - Processing file /opt/airflow/dags/my_first_dag.py for tasks to queue
[2024-04-29T17:54:08.275+0000] {logging_mixin.py:188} INFO - [2024-04-29T17:54:08.274+0000] {dagbag.py:540} INFO - Filling up the DagBag from /opt/airflow/dags/my_first_dag.py
[2024-04-29T17:54:08.277+0000] {logging_mixin.py:188} INFO - [2024-04-29T17:54:08.277+0000] {dagbag.py:350} ERROR - Failed to import: /opt/airflow/dags/my_first_dag.py
Traceback (most recent call last):
  File "/home/airflow/.local/lib/python3.8/site-packages/airflow/models/dagbag.py", line 346, in parse
    loader.exec_module(new_module)
  File "<frozen importlib._bootstrap_external>", line 839, in exec_module
  File "<frozen importlib._bootstrap_external>", line 976, in get_code
  File "<frozen importlib._bootstrap_external>", line 906, in source_to_code
  File "<frozen importlib._bootstrap>", line 219, in _call_with_frames_removed
  File "/opt/airflow/dags/my_first_dag.py", line 19
    start_date=,
               ^
SyntaxError: invalid syntax
[2024-04-29T17:54:08.278+0000] {processor.py:842} WARNING - No viable dags retrieved from /opt/airflow/dags/my_first_dag.py
[2024-04-29T17:54:08.311+0000] {processor.py:183} INFO - Processing /opt/airflow/dags/my_first_dag.py took 0.041 seconds
[2024-04-29T17:54:10.184+0000] {processor.py:161} INFO - Started process (PID=12408) to work on /opt/airflow/dags/my_first_dag.py
[2024-04-29T17:54:10.184+0000] {processor.py:830} INFO - Processing file /opt/airflow/dags/my_first_dag.py for tasks to queue
[2024-04-29T17:54:10.185+0000] {logging_mixin.py:188} INFO - [2024-04-29T17:54:10.185+0000] {dagbag.py:540} INFO - Filling up the DagBag from /opt/airflow/dags/my_first_dag.py
[2024-04-29T17:54:10.187+0000] {logging_mixin.py:188} INFO - [2024-04-29T17:54:10.187+0000] {dagbag.py:350} ERROR - Failed to import: /opt/airflow/dags/my_first_dag.py
Traceback (most recent call last):
  File "/home/airflow/.local/lib/python3.8/site-packages/airflow/models/dagbag.py", line 346, in parse
    loader.exec_module(new_module)
  File "<frozen importlib._bootstrap_external>", line 839, in exec_module
  File "<frozen importlib._bootstrap_external>", line 976, in get_code
  File "<frozen importlib._bootstrap_external>", line 906, in source_to_code
  File "<frozen importlib._bootstrap>", line 219, in _call_with_frames_removed
  File "/opt/airflow/dags/my_first_dag.py", line 19
    start_date=,
               ^
SyntaxError: invalid syntax
[2024-04-29T17:54:10.188+0000] {processor.py:842} WARNING - No viable dags retrieved from /opt/airflow/dags/my_first_dag.py
[2024-04-29T17:54:10.209+0000] {processor.py:183} INFO - Processing /opt/airflow/dags/my_first_dag.py took 0.028 seconds
[2024-04-29T17:54:13.233+0000] {processor.py:161} INFO - Started process (PID=12413) to work on /opt/airflow/dags/my_first_dag.py
[2024-04-29T17:54:13.234+0000] {processor.py:830} INFO - Processing file /opt/airflow/dags/my_first_dag.py for tasks to queue
[2024-04-29T17:54:13.235+0000] {logging_mixin.py:188} INFO - [2024-04-29T17:54:13.234+0000] {dagbag.py:540} INFO - Filling up the DagBag from /opt/airflow/dags/my_first_dag.py
[2024-04-29T17:54:13.237+0000] {logging_mixin.py:188} INFO - [2024-04-29T17:54:13.236+0000] {dagbag.py:350} ERROR - Failed to import: /opt/airflow/dags/my_first_dag.py
Traceback (most recent call last):
  File "/home/airflow/.local/lib/python3.8/site-packages/airflow/models/dagbag.py", line 346, in parse
    loader.exec_module(new_module)
  File "<frozen importlib._bootstrap_external>", line 839, in exec_module
  File "<frozen importlib._bootstrap_external>", line 976, in get_code
  File "<frozen importlib._bootstrap_external>", line 906, in source_to_code
  File "<frozen importlib._bootstrap>", line 219, in _call_with_frames_removed
  File "/opt/airflow/dags/my_first_dag.py", line 18
    start_date=,
               ^
SyntaxError: invalid syntax
[2024-04-29T17:54:13.237+0000] {processor.py:842} WARNING - No viable dags retrieved from /opt/airflow/dags/my_first_dag.py
[2024-04-29T17:54:13.258+0000] {processor.py:183} INFO - Processing /opt/airflow/dags/my_first_dag.py took 0.027 seconds
[2024-04-29T17:54:18.276+0000] {processor.py:161} INFO - Started process (PID=12424) to work on /opt/airflow/dags/my_first_dag.py
[2024-04-29T17:54:18.277+0000] {processor.py:830} INFO - Processing file /opt/airflow/dags/my_first_dag.py for tasks to queue
[2024-04-29T17:54:18.278+0000] {logging_mixin.py:188} INFO - [2024-04-29T17:54:18.278+0000] {dagbag.py:540} INFO - Filling up the DagBag from /opt/airflow/dags/my_first_dag.py
[2024-04-29T17:54:18.280+0000] {logging_mixin.py:188} INFO - [2024-04-29T17:54:18.280+0000] {dagbag.py:350} ERROR - Failed to import: /opt/airflow/dags/my_first_dag.py
Traceback (most recent call last):
  File "/home/airflow/.local/lib/python3.8/site-packages/airflow/models/dagbag.py", line 346, in parse
    loader.exec_module(new_module)
  File "<frozen importlib._bootstrap_external>", line 839, in exec_module
  File "<frozen importlib._bootstrap_external>", line 976, in get_code
  File "<frozen importlib._bootstrap_external>", line 906, in source_to_code
  File "<frozen importlib._bootstrap>", line 219, in _call_with_frames_removed
  File "/opt/airflow/dags/my_first_dag.py", line 18
    start_date=,
               ^
SyntaxError: invalid syntax
[2024-04-29T17:54:18.281+0000] {processor.py:842} WARNING - No viable dags retrieved from /opt/airflow/dags/my_first_dag.py
[2024-04-29T17:54:18.305+0000] {processor.py:183} INFO - Processing /opt/airflow/dags/my_first_dag.py took 0.032 seconds
[2024-04-29T17:54:21.310+0000] {processor.py:161} INFO - Started process (PID=12429) to work on /opt/airflow/dags/my_first_dag.py
[2024-04-29T17:54:21.311+0000] {processor.py:830} INFO - Processing file /opt/airflow/dags/my_first_dag.py for tasks to queue
[2024-04-29T17:54:21.312+0000] {logging_mixin.py:188} INFO - [2024-04-29T17:54:21.311+0000] {dagbag.py:540} INFO - Filling up the DagBag from /opt/airflow/dags/my_first_dag.py
[2024-04-29T17:54:21.314+0000] {logging_mixin.py:188} INFO - [2024-04-29T17:54:21.313+0000] {dagbag.py:350} ERROR - Failed to import: /opt/airflow/dags/my_first_dag.py
Traceback (most recent call last):
  File "/home/airflow/.local/lib/python3.8/site-packages/airflow/models/dagbag.py", line 346, in parse
    loader.exec_module(new_module)
  File "<frozen importlib._bootstrap_external>", line 839, in exec_module
  File "<frozen importlib._bootstrap_external>", line 976, in get_code
  File "<frozen importlib._bootstrap_external>", line 906, in source_to_code
  File "<frozen importlib._bootstrap>", line 219, in _call_with_frames_removed
  File "/opt/airflow/dags/my_first_dag.py", line 18
    start_date=,
               ^
SyntaxError: invalid syntax
[2024-04-29T17:54:21.314+0000] {processor.py:842} WARNING - No viable dags retrieved from /opt/airflow/dags/my_first_dag.py
[2024-04-29T17:54:21.337+0000] {processor.py:183} INFO - Processing /opt/airflow/dags/my_first_dag.py took 0.030 seconds
[2024-04-29T17:54:52.003+0000] {processor.py:161} INFO - Started process (PID=12681) to work on /opt/airflow/dags/my_first_dag.py
[2024-04-29T17:54:52.003+0000] {processor.py:830} INFO - Processing file /opt/airflow/dags/my_first_dag.py for tasks to queue
[2024-04-29T17:54:52.004+0000] {logging_mixin.py:188} INFO - [2024-04-29T17:54:52.004+0000] {dagbag.py:540} INFO - Filling up the DagBag from /opt/airflow/dags/my_first_dag.py
[2024-04-29T17:54:52.006+0000] {logging_mixin.py:188} INFO - [2024-04-29T17:54:52.006+0000] {dagbag.py:350} ERROR - Failed to import: /opt/airflow/dags/my_first_dag.py
Traceback (most recent call last):
  File "/home/airflow/.local/lib/python3.8/site-packages/airflow/models/dagbag.py", line 346, in parse
    loader.exec_module(new_module)
  File "<frozen importlib._bootstrap_external>", line 839, in exec_module
  File "<frozen importlib._bootstrap_external>", line 976, in get_code
  File "<frozen importlib._bootstrap_external>", line 906, in source_to_code
  File "<frozen importlib._bootstrap>", line 219, in _call_with_frames_removed
  File "/opt/airflow/dags/my_first_dag.py", line 18
    start_date=,
               ^
SyntaxError: invalid syntax
[2024-04-29T17:54:52.007+0000] {processor.py:842} WARNING - No viable dags retrieved from /opt/airflow/dags/my_first_dag.py
[2024-04-29T17:54:52.027+0000] {processor.py:183} INFO - Processing /opt/airflow/dags/my_first_dag.py took 0.027 seconds
[2024-04-29T17:55:15.696+0000] {processor.py:161} INFO - Started process (PID=12927) to work on /opt/airflow/dags/my_first_dag.py
[2024-04-29T17:55:15.697+0000] {processor.py:830} INFO - Processing file /opt/airflow/dags/my_first_dag.py for tasks to queue
[2024-04-29T17:55:15.698+0000] {logging_mixin.py:188} INFO - [2024-04-29T17:55:15.697+0000] {dagbag.py:540} INFO - Filling up the DagBag from /opt/airflow/dags/my_first_dag.py
[2024-04-29T17:55:15.700+0000] {logging_mixin.py:188} INFO - [2024-04-29T17:55:15.699+0000] {dagbag.py:350} ERROR - Failed to import: /opt/airflow/dags/my_first_dag.py
Traceback (most recent call last):
  File "/home/airflow/.local/lib/python3.8/site-packages/airflow/models/dagbag.py", line 346, in parse
    loader.exec_module(new_module)
  File "<frozen importlib._bootstrap_external>", line 839, in exec_module
  File "<frozen importlib._bootstrap_external>", line 976, in get_code
  File "<frozen importlib._bootstrap_external>", line 906, in source_to_code
  File "<frozen importlib._bootstrap>", line 219, in _call_with_frames_removed
  File "/opt/airflow/dags/my_first_dag.py", line 2
    from airflow.utils import
                             ^
SyntaxError: invalid syntax
[2024-04-29T17:55:15.701+0000] {processor.py:842} WARNING - No viable dags retrieved from /opt/airflow/dags/my_first_dag.py
[2024-04-29T17:55:15.728+0000] {processor.py:183} INFO - Processing /opt/airflow/dags/my_first_dag.py took 0.034 seconds
[2024-04-29T17:55:21.739+0000] {processor.py:161} INFO - Started process (PID=12938) to work on /opt/airflow/dags/my_first_dag.py
[2024-04-29T17:55:21.740+0000] {processor.py:830} INFO - Processing file /opt/airflow/dags/my_first_dag.py for tasks to queue
[2024-04-29T17:55:21.741+0000] {logging_mixin.py:188} INFO - [2024-04-29T17:55:21.740+0000] {dagbag.py:540} INFO - Filling up the DagBag from /opt/airflow/dags/my_first_dag.py
[2024-04-29T17:55:21.743+0000] {logging_mixin.py:188} INFO - [2024-04-29T17:55:21.742+0000] {dagbag.py:350} ERROR - Failed to import: /opt/airflow/dags/my_first_dag.py
Traceback (most recent call last):
  File "/home/airflow/.local/lib/python3.8/site-packages/airflow/models/dagbag.py", line 346, in parse
    loader.exec_module(new_module)
  File "<frozen importlib._bootstrap_external>", line 839, in exec_module
  File "<frozen importlib._bootstrap_external>", line 976, in get_code
  File "<frozen importlib._bootstrap_external>", line 906, in source_to_code
  File "<frozen importlib._bootstrap>", line 219, in _call_with_frames_removed
  File "/opt/airflow/dags/my_first_dag.py", line 20
    start_date=,
               ^
SyntaxError: invalid syntax
[2024-04-29T17:55:21.743+0000] {processor.py:842} WARNING - No viable dags retrieved from /opt/airflow/dags/my_first_dag.py
[2024-04-29T17:55:21.764+0000] {processor.py:183} INFO - Processing /opt/airflow/dags/my_first_dag.py took 0.027 seconds
[2024-04-29T17:55:32.215+0000] {processor.py:161} INFO - Started process (PID=13054) to work on /opt/airflow/dags/my_first_dag.py
[2024-04-29T17:55:32.216+0000] {processor.py:830} INFO - Processing file /opt/airflow/dags/my_first_dag.py for tasks to queue
[2024-04-29T17:55:32.218+0000] {logging_mixin.py:188} INFO - [2024-04-29T17:55:32.217+0000] {dagbag.py:540} INFO - Filling up the DagBag from /opt/airflow/dags/my_first_dag.py
[2024-04-29T17:55:32.221+0000] {logging_mixin.py:188} INFO - [2024-04-29T17:55:32.220+0000] {dagbag.py:350} ERROR - Failed to import: /opt/airflow/dags/my_first_dag.py
Traceback (most recent call last):
  File "/home/airflow/.local/lib/python3.8/site-packages/airflow/models/dagbag.py", line 346, in parse
    loader.exec_module(new_module)
  File "<frozen importlib._bootstrap_external>", line 839, in exec_module
  File "<frozen importlib._bootstrap_external>", line 976, in get_code
  File "<frozen importlib._bootstrap_external>", line 906, in source_to_code
  File "<frozen importlib._bootstrap>", line 219, in _call_with_frames_removed
  File "/opt/airflow/dags/my_first_dag.py", line 23
    ):
     ^
SyntaxError: unexpected EOF while parsing
[2024-04-29T17:55:32.221+0000] {processor.py:842} WARNING - No viable dags retrieved from /opt/airflow/dags/my_first_dag.py
[2024-04-29T17:55:32.253+0000] {processor.py:183} INFO - Processing /opt/airflow/dags/my_first_dag.py took 0.041 seconds
[2024-04-29T17:55:42.038+0000] {processor.py:161} INFO - Started process (PID=13189) to work on /opt/airflow/dags/my_first_dag.py
[2024-04-29T17:55:42.039+0000] {processor.py:830} INFO - Processing file /opt/airflow/dags/my_first_dag.py for tasks to queue
[2024-04-29T17:55:42.039+0000] {logging_mixin.py:188} INFO - [2024-04-29T17:55:42.039+0000] {dagbag.py:540} INFO - Filling up the DagBag from /opt/airflow/dags/my_first_dag.py
[2024-04-29T17:55:42.042+0000] {logging_mixin.py:188} INFO - [2024-04-29T17:55:42.041+0000] {dagbag.py:350} ERROR - Failed to import: /opt/airflow/dags/my_first_dag.py
Traceback (most recent call last):
  File "/home/airflow/.local/lib/python3.8/site-packages/airflow/models/dagbag.py", line 346, in parse
    loader.exec_module(new_module)
  File "<frozen importlib._bootstrap_external>", line 839, in exec_module
  File "<frozen importlib._bootstrap_external>", line 976, in get_code
  File "<frozen importlib._bootstrap_external>", line 906, in source_to_code
  File "<frozen importlib._bootstrap>", line 219, in _call_with_frames_removed
  File "/opt/airflow/dags/my_first_dag.py", line 20
    start_date=timezone.datatime(2024, 03, 23),
                                        ^
SyntaxError: leading zeros in decimal integer literals are not permitted; use an 0o prefix for octal integers
[2024-04-29T17:55:42.043+0000] {processor.py:842} WARNING - No viable dags retrieved from /opt/airflow/dags/my_first_dag.py
[2024-04-29T17:55:42.066+0000] {processor.py:183} INFO - Processing /opt/airflow/dags/my_first_dag.py took 0.032 seconds
[2024-04-29T17:55:46.071+0000] {processor.py:161} INFO - Started process (PID=13194) to work on /opt/airflow/dags/my_first_dag.py
[2024-04-29T17:55:46.072+0000] {processor.py:830} INFO - Processing file /opt/airflow/dags/my_first_dag.py for tasks to queue
[2024-04-29T17:55:46.073+0000] {logging_mixin.py:188} INFO - [2024-04-29T17:55:46.073+0000] {dagbag.py:540} INFO - Filling up the DagBag from /opt/airflow/dags/my_first_dag.py
[2024-04-29T17:55:46.075+0000] {logging_mixin.py:188} INFO - [2024-04-29T17:55:46.075+0000] {dagbag.py:350} ERROR - Failed to import: /opt/airflow/dags/my_first_dag.py
Traceback (most recent call last):
  File "/home/airflow/.local/lib/python3.8/site-packages/airflow/models/dagbag.py", line 346, in parse
    loader.exec_module(new_module)
  File "<frozen importlib._bootstrap_external>", line 839, in exec_module
  File "<frozen importlib._bootstrap_external>", line 976, in get_code
  File "<frozen importlib._bootstrap_external>", line 906, in source_to_code
  File "<frozen importlib._bootstrap>", line 219, in _call_with_frames_removed
  File "/opt/airflow/dags/my_first_dag.py", line 23
    ):
     ^
SyntaxError: unexpected EOF while parsing
[2024-04-29T17:55:46.075+0000] {processor.py:842} WARNING - No viable dags retrieved from /opt/airflow/dags/my_first_dag.py
[2024-04-29T17:55:46.100+0000] {processor.py:183} INFO - Processing /opt/airflow/dags/my_first_dag.py took 0.031 seconds
[2024-04-29T17:56:05.232+0000] {processor.py:161} INFO - Started process (PID=13371) to work on /opt/airflow/dags/my_first_dag.py
[2024-04-29T17:56:05.233+0000] {processor.py:830} INFO - Processing file /opt/airflow/dags/my_first_dag.py for tasks to queue
[2024-04-29T17:56:05.234+0000] {logging_mixin.py:188} INFO - [2024-04-29T17:56:05.234+0000] {dagbag.py:540} INFO - Filling up the DagBag from /opt/airflow/dags/my_first_dag.py
[2024-04-29T17:56:05.237+0000] {logging_mixin.py:188} INFO - [2024-04-29T17:56:05.236+0000] {dagbag.py:350} ERROR - Failed to import: /opt/airflow/dags/my_first_dag.py
Traceback (most recent call last):
  File "/home/airflow/.local/lib/python3.8/site-packages/airflow/models/dagbag.py", line 346, in parse
    loader.exec_module(new_module)
  File "<frozen importlib._bootstrap_external>", line 839, in exec_module
  File "<frozen importlib._bootstrap_external>", line 976, in get_code
  File "<frozen importlib._bootstrap_external>", line 906, in source_to_code
  File "<frozen importlib._bootstrap>", line 219, in _call_with_frames_removed
  File "/opt/airflow/dags/my_first_dag.py", line 23
    ):
     ^
SyntaxError: unexpected EOF while parsing
[2024-04-29T17:56:05.238+0000] {processor.py:842} WARNING - No viable dags retrieved from /opt/airflow/dags/my_first_dag.py
[2024-04-29T17:56:05.283+0000] {processor.py:183} INFO - Processing /opt/airflow/dags/my_first_dag.py took 0.054 seconds
[2024-04-29T17:56:12.330+0000] {processor.py:161} INFO - Started process (PID=13451) to work on /opt/airflow/dags/my_first_dag.py
[2024-04-29T17:56:12.331+0000] {processor.py:830} INFO - Processing file /opt/airflow/dags/my_first_dag.py for tasks to queue
[2024-04-29T17:56:12.332+0000] {logging_mixin.py:188} INFO - [2024-04-29T17:56:12.332+0000] {dagbag.py:540} INFO - Filling up the DagBag from /opt/airflow/dags/my_first_dag.py
[2024-04-29T17:56:12.334+0000] {logging_mixin.py:188} INFO - [2024-04-29T17:56:12.333+0000] {dagbag.py:350} ERROR - Failed to import: /opt/airflow/dags/my_first_dag.py
Traceback (most recent call last):
  File "/home/airflow/.local/lib/python3.8/site-packages/airflow/models/dagbag.py", line 346, in parse
    loader.exec_module(new_module)
  File "<frozen importlib._bootstrap_external>", line 839, in exec_module
  File "<frozen importlib._bootstrap_external>", line 976, in get_code
  File "<frozen importlib._bootstrap_external>", line 906, in source_to_code
  File "<frozen importlib._bootstrap>", line 219, in _call_with_frames_removed
  File "/opt/airflow/dags/my_first_dag.py", line 23
    ):
     ^
SyntaxError: unexpected EOF while parsing
[2024-04-29T17:56:12.334+0000] {processor.py:842} WARNING - No viable dags retrieved from /opt/airflow/dags/my_first_dag.py
[2024-04-29T17:56:12.355+0000] {processor.py:183} INFO - Processing /opt/airflow/dags/my_first_dag.py took 0.027 seconds
[2024-04-29T17:56:42.715+0000] {processor.py:161} INFO - Started process (PID=13703) to work on /opt/airflow/dags/my_first_dag.py
[2024-04-29T17:56:42.716+0000] {processor.py:830} INFO - Processing file /opt/airflow/dags/my_first_dag.py for tasks to queue
[2024-04-29T17:56:42.717+0000] {logging_mixin.py:188} INFO - [2024-04-29T17:56:42.716+0000] {dagbag.py:540} INFO - Filling up the DagBag from /opt/airflow/dags/my_first_dag.py
[2024-04-29T17:56:42.719+0000] {logging_mixin.py:188} INFO - [2024-04-29T17:56:42.718+0000] {dagbag.py:350} ERROR - Failed to import: /opt/airflow/dags/my_first_dag.py
Traceback (most recent call last):
  File "/home/airflow/.local/lib/python3.8/site-packages/airflow/models/dagbag.py", line 346, in parse
    loader.exec_module(new_module)
  File "<frozen importlib._bootstrap_external>", line 839, in exec_module
  File "<frozen importlib._bootstrap_external>", line 976, in get_code
  File "<frozen importlib._bootstrap_external>", line 906, in source_to_code
  File "<frozen importlib._bootstrap>", line 219, in _call_with_frames_removed
  File "/opt/airflow/dags/my_first_dag.py", line 23
    ):
     ^
SyntaxError: unexpected EOF while parsing
[2024-04-29T17:56:42.719+0000] {processor.py:842} WARNING - No viable dags retrieved from /opt/airflow/dags/my_first_dag.py
[2024-04-29T17:56:42.740+0000] {processor.py:183} INFO - Processing /opt/airflow/dags/my_first_dag.py took 0.028 seconds
[2024-04-29T17:56:49.780+0000] {processor.py:161} INFO - Started process (PID=13715) to work on /opt/airflow/dags/my_first_dag.py
[2024-04-29T17:56:49.781+0000] {processor.py:830} INFO - Processing file /opt/airflow/dags/my_first_dag.py for tasks to queue
[2024-04-29T17:56:49.782+0000] {logging_mixin.py:188} INFO - [2024-04-29T17:56:49.781+0000] {dagbag.py:540} INFO - Filling up the DagBag from /opt/airflow/dags/my_first_dag.py
[2024-04-29T17:56:49.785+0000] {logging_mixin.py:188} INFO - [2024-04-29T17:56:49.784+0000] {dagbag.py:350} ERROR - Failed to import: /opt/airflow/dags/my_first_dag.py
Traceback (most recent call last):
  File "/home/airflow/.local/lib/python3.8/site-packages/airflow/models/dagbag.py", line 346, in parse
    loader.exec_module(new_module)
  File "<frozen importlib._bootstrap_external>", line 839, in exec_module
  File "<frozen importlib._bootstrap_external>", line 976, in get_code
  File "<frozen importlib._bootstrap_external>", line 906, in source_to_code
  File "<frozen importlib._bootstrap>", line 219, in _call_with_frames_removed
  File "/opt/airflow/dags/my_first_dag.py", line 24
    
    ^
SyntaxError: unexpected EOF while parsing
[2024-04-29T17:56:49.785+0000] {processor.py:842} WARNING - No viable dags retrieved from /opt/airflow/dags/my_first_dag.py
[2024-04-29T17:56:49.808+0000] {processor.py:183} INFO - Processing /opt/airflow/dags/my_first_dag.py took 0.033 seconds
[2024-04-29T17:56:51.811+0000] {processor.py:161} INFO - Started process (PID=13720) to work on /opt/airflow/dags/my_first_dag.py
[2024-04-29T17:56:51.812+0000] {processor.py:830} INFO - Processing file /opt/airflow/dags/my_first_dag.py for tasks to queue
[2024-04-29T17:56:51.813+0000] {logging_mixin.py:188} INFO - [2024-04-29T17:56:51.812+0000] {dagbag.py:540} INFO - Filling up the DagBag from /opt/airflow/dags/my_first_dag.py
[2024-04-29T17:56:51.815+0000] {logging_mixin.py:188} INFO - [2024-04-29T17:56:51.814+0000] {dagbag.py:350} ERROR - Failed to import: /opt/airflow/dags/my_first_dag.py
Traceback (most recent call last):
  File "/home/airflow/.local/lib/python3.8/site-packages/airflow/models/dagbag.py", line 346, in parse
    loader.exec_module(new_module)
  File "<frozen importlib._bootstrap_external>", line 839, in exec_module
  File "<frozen importlib._bootstrap_external>", line 976, in get_code
  File "<frozen importlib._bootstrap_external>", line 906, in source_to_code
  File "<frozen importlib._bootstrap>", line 219, in _call_with_frames_removed
  File "/opt/airflow/dags/my_first_dag.py", line 25
    Em
    ^
IndentationError: expected an indented block
[2024-04-29T17:56:51.815+0000] {processor.py:842} WARNING - No viable dags retrieved from /opt/airflow/dags/my_first_dag.py
[2024-04-29T17:56:51.837+0000] {processor.py:183} INFO - Processing /opt/airflow/dags/my_first_dag.py took 0.029 seconds
[2024-04-29T17:56:56.398+0000] {processor.py:161} INFO - Started process (PID=13768) to work on /opt/airflow/dags/my_first_dag.py
[2024-04-29T17:56:56.400+0000] {processor.py:830} INFO - Processing file /opt/airflow/dags/my_first_dag.py for tasks to queue
[2024-04-29T17:56:56.401+0000] {logging_mixin.py:188} INFO - [2024-04-29T17:56:56.400+0000] {dagbag.py:540} INFO - Filling up the DagBag from /opt/airflow/dags/my_first_dag.py
[2024-04-29T17:56:56.404+0000] {logging_mixin.py:188} INFO - [2024-04-29T17:56:56.403+0000] {dagbag.py:350} ERROR - Failed to import: /opt/airflow/dags/my_first_dag.py
Traceback (most recent call last):
  File "/home/airflow/.local/lib/python3.8/site-packages/airflow/models/dagbag.py", line 346, in parse
    loader.exec_module(new_module)
  File "<frozen importlib._bootstrap_external>", line 843, in exec_module
  File "<frozen importlib._bootstrap>", line 219, in _call_with_frames_removed
  File "/opt/airflow/dags/my_first_dag.py", line 20, in <module>
    start_date=timezone.datatime(2024, 3, 23),
AttributeError: module 'airflow.utils.timezone' has no attribute 'datatime'
[2024-04-29T17:56:56.405+0000] {processor.py:842} WARNING - No viable dags retrieved from /opt/airflow/dags/my_first_dag.py
[2024-04-29T17:56:56.437+0000] {processor.py:183} INFO - Processing /opt/airflow/dags/my_first_dag.py took 0.043 seconds
[2024-04-29T17:56:57.469+0000] {processor.py:161} INFO - Started process (PID=13775) to work on /opt/airflow/dags/my_first_dag.py
[2024-04-29T17:56:57.470+0000] {processor.py:830} INFO - Processing file /opt/airflow/dags/my_first_dag.py for tasks to queue
[2024-04-29T17:56:57.471+0000] {logging_mixin.py:188} INFO - [2024-04-29T17:56:57.470+0000] {dagbag.py:540} INFO - Filling up the DagBag from /opt/airflow/dags/my_first_dag.py
[2024-04-29T17:56:57.475+0000] {logging_mixin.py:188} INFO - [2024-04-29T17:56:57.474+0000] {dagbag.py:350} ERROR - Failed to import: /opt/airflow/dags/my_first_dag.py
Traceback (most recent call last):
  File "/home/airflow/.local/lib/python3.8/site-packages/airflow/models/dagbag.py", line 346, in parse
    loader.exec_module(new_module)
  File "<frozen importlib._bootstrap_external>", line 843, in exec_module
  File "<frozen importlib._bootstrap>", line 219, in _call_with_frames_removed
  File "/opt/airflow/dags/my_first_dag.py", line 20, in <module>
    start_date=timezone.datatime(2024, 3, 23),
AttributeError: module 'airflow.utils.timezone' has no attribute 'datatime'
[2024-04-29T17:56:57.475+0000] {processor.py:842} WARNING - No viable dags retrieved from /opt/airflow/dags/my_first_dag.py
[2024-04-29T17:56:57.503+0000] {processor.py:183} INFO - Processing /opt/airflow/dags/my_first_dag.py took 0.037 seconds
[2024-04-29T17:57:06.094+0000] {processor.py:161} INFO - Started process (PID=13901) to work on /opt/airflow/dags/my_first_dag.py
[2024-04-29T17:57:06.095+0000] {processor.py:830} INFO - Processing file /opt/airflow/dags/my_first_dag.py for tasks to queue
[2024-04-29T17:57:06.096+0000] {logging_mixin.py:188} INFO - [2024-04-29T17:57:06.096+0000] {dagbag.py:540} INFO - Filling up the DagBag from /opt/airflow/dags/my_first_dag.py
[2024-04-29T17:57:06.100+0000] {logging_mixin.py:188} INFO - [2024-04-29T17:57:06.099+0000] {dagbag.py:350} ERROR - Failed to import: /opt/airflow/dags/my_first_dag.py
Traceback (most recent call last):
  File "/home/airflow/.local/lib/python3.8/site-packages/airflow/models/dagbag.py", line 346, in parse
    loader.exec_module(new_module)
  File "<frozen importlib._bootstrap_external>", line 843, in exec_module
  File "<frozen importlib._bootstrap>", line 219, in _call_with_frames_removed
  File "/opt/airflow/dags/my_first_dag.py", line 20, in <module>
    start_date=timezone.datatime(2024, 3, 23),
AttributeError: module 'airflow.utils.timezone' has no attribute 'datatime'
[2024-04-29T17:57:06.100+0000] {processor.py:842} WARNING - No viable dags retrieved from /opt/airflow/dags/my_first_dag.py
[2024-04-29T17:57:06.128+0000] {processor.py:183} INFO - Processing /opt/airflow/dags/my_first_dag.py took 0.038 seconds
[2024-04-29T17:57:17.207+0000] {processor.py:161} INFO - Started process (PID=13981) to work on /opt/airflow/dags/my_first_dag.py
[2024-04-29T17:57:17.208+0000] {processor.py:830} INFO - Processing file /opt/airflow/dags/my_first_dag.py for tasks to queue
[2024-04-29T17:57:17.208+0000] {logging_mixin.py:188} INFO - [2024-04-29T17:57:17.208+0000] {dagbag.py:540} INFO - Filling up the DagBag from /opt/airflow/dags/my_first_dag.py
[2024-04-29T17:57:17.211+0000] {logging_mixin.py:188} INFO - [2024-04-29T17:57:17.210+0000] {dagbag.py:350} ERROR - Failed to import: /opt/airflow/dags/my_first_dag.py
Traceback (most recent call last):
  File "/home/airflow/.local/lib/python3.8/site-packages/airflow/models/dagbag.py", line 346, in parse
    loader.exec_module(new_module)
  File "<frozen importlib._bootstrap_external>", line 843, in exec_module
  File "<frozen importlib._bootstrap>", line 219, in _call_with_frames_removed
  File "/opt/airflow/dags/my_first_dag.py", line 20, in <module>
    start_date=timezone.datatime(2024, 3, 23),
AttributeError: module 'airflow.utils.timezone' has no attribute 'datatime'
[2024-04-29T17:57:17.211+0000] {processor.py:842} WARNING - No viable dags retrieved from /opt/airflow/dags/my_first_dag.py
[2024-04-29T17:57:17.233+0000] {processor.py:183} INFO - Processing /opt/airflow/dags/my_first_dag.py took 0.029 seconds
[2024-04-29T17:57:20.227+0000] {processor.py:161} INFO - Started process (PID=13993) to work on /opt/airflow/dags/my_first_dag.py
[2024-04-29T17:57:20.228+0000] {processor.py:830} INFO - Processing file /opt/airflow/dags/my_first_dag.py for tasks to queue
[2024-04-29T17:57:20.229+0000] {logging_mixin.py:188} INFO - [2024-04-29T17:57:20.228+0000] {dagbag.py:540} INFO - Filling up the DagBag from /opt/airflow/dags/my_first_dag.py
[2024-04-29T17:57:20.233+0000] {logging_mixin.py:188} INFO - [2024-04-29T17:57:20.232+0000] {dagbag.py:350} ERROR - Failed to import: /opt/airflow/dags/my_first_dag.py
Traceback (most recent call last):
  File "/home/airflow/.local/lib/python3.8/site-packages/airflow/models/dagbag.py", line 346, in parse
    loader.exec_module(new_module)
  File "<frozen importlib._bootstrap_external>", line 843, in exec_module
  File "<frozen importlib._bootstrap>", line 219, in _call_with_frames_removed
  File "/opt/airflow/dags/my_first_dag.py", line 20, in <module>
    start_date=timezone.datatime(2024, 3, 23),
AttributeError: module 'airflow.utils.timezone' has no attribute 'datatime'
[2024-04-29T17:57:20.235+0000] {processor.py:842} WARNING - No viable dags retrieved from /opt/airflow/dags/my_first_dag.py
[2024-04-29T17:57:20.270+0000] {processor.py:183} INFO - Processing /opt/airflow/dags/my_first_dag.py took 0.046 seconds
[2024-04-29T17:57:27.830+0000] {processor.py:161} INFO - Started process (PID=14043) to work on /opt/airflow/dags/my_first_dag.py
[2024-04-29T17:57:27.830+0000] {processor.py:830} INFO - Processing file /opt/airflow/dags/my_first_dag.py for tasks to queue
[2024-04-29T17:57:27.831+0000] {logging_mixin.py:188} INFO - [2024-04-29T17:57:27.831+0000] {dagbag.py:540} INFO - Filling up the DagBag from /opt/airflow/dags/my_first_dag.py
[2024-04-29T17:57:27.834+0000] {logging_mixin.py:188} INFO - [2024-04-29T17:57:27.834+0000] {dagbag.py:350} ERROR - Failed to import: /opt/airflow/dags/my_first_dag.py
Traceback (most recent call last):
  File "/home/airflow/.local/lib/python3.8/site-packages/airflow/models/dagbag.py", line 346, in parse
    loader.exec_module(new_module)
  File "<frozen importlib._bootstrap_external>", line 843, in exec_module
  File "<frozen importlib._bootstrap>", line 219, in _call_with_frames_removed
  File "/opt/airflow/dags/my_first_dag.py", line 20, in <module>
    start_date=timezone.datatime(2024, 3, 23),
AttributeError: module 'airflow.utils.timezone' has no attribute 'datatime'
[2024-04-29T17:57:27.835+0000] {processor.py:842} WARNING - No viable dags retrieved from /opt/airflow/dags/my_first_dag.py
[2024-04-29T17:57:27.862+0000] {processor.py:183} INFO - Processing /opt/airflow/dags/my_first_dag.py took 0.035 seconds
[2024-04-29T17:57:36.730+0000] {processor.py:161} INFO - Started process (PID=14169) to work on /opt/airflow/dags/my_first_dag.py
[2024-04-29T17:57:36.731+0000] {processor.py:830} INFO - Processing file /opt/airflow/dags/my_first_dag.py for tasks to queue
[2024-04-29T17:57:36.732+0000] {logging_mixin.py:188} INFO - [2024-04-29T17:57:36.732+0000] {dagbag.py:540} INFO - Filling up the DagBag from /opt/airflow/dags/my_first_dag.py
[2024-04-29T17:57:36.736+0000] {logging_mixin.py:188} INFO - [2024-04-29T17:57:36.735+0000] {dagbag.py:350} ERROR - Failed to import: /opt/airflow/dags/my_first_dag.py
Traceback (most recent call last):
  File "/home/airflow/.local/lib/python3.8/site-packages/airflow/models/dagbag.py", line 346, in parse
    loader.exec_module(new_module)
  File "<frozen importlib._bootstrap_external>", line 843, in exec_module
  File "<frozen importlib._bootstrap>", line 219, in _call_with_frames_removed
  File "/opt/airflow/dags/my_first_dag.py", line 20, in <module>
    start_date=timezone.datatime(2024, 3, 23),
AttributeError: module 'airflow.utils.timezone' has no attribute 'datatime'
[2024-04-29T17:57:36.736+0000] {processor.py:842} WARNING - No viable dags retrieved from /opt/airflow/dags/my_first_dag.py
[2024-04-29T17:57:36.764+0000] {processor.py:183} INFO - Processing /opt/airflow/dags/my_first_dag.py took 0.037 seconds
[2024-04-29T17:57:45.746+0000] {processor.py:161} INFO - Started process (PID=14249) to work on /opt/airflow/dags/my_first_dag.py
[2024-04-29T17:57:45.746+0000] {processor.py:830} INFO - Processing file /opt/airflow/dags/my_first_dag.py for tasks to queue
[2024-04-29T17:57:45.747+0000] {logging_mixin.py:188} INFO - [2024-04-29T17:57:45.747+0000] {dagbag.py:540} INFO - Filling up the DagBag from /opt/airflow/dags/my_first_dag.py
[2024-04-29T17:57:45.750+0000] {logging_mixin.py:188} INFO - [2024-04-29T17:57:45.749+0000] {dagbag.py:350} ERROR - Failed to import: /opt/airflow/dags/my_first_dag.py
Traceback (most recent call last):
  File "/home/airflow/.local/lib/python3.8/site-packages/airflow/models/dagbag.py", line 346, in parse
    loader.exec_module(new_module)
  File "<frozen importlib._bootstrap_external>", line 843, in exec_module
  File "<frozen importlib._bootstrap>", line 219, in _call_with_frames_removed
  File "/opt/airflow/dags/my_first_dag.py", line 20, in <module>
    start_date=timezone.datatime(2024, 3, 23),
AttributeError: module 'airflow.utils.timezone' has no attribute 'datatime'
[2024-04-29T17:57:45.750+0000] {processor.py:842} WARNING - No viable dags retrieved from /opt/airflow/dags/my_first_dag.py
[2024-04-29T17:57:45.774+0000] {processor.py:183} INFO - Processing /opt/airflow/dags/my_first_dag.py took 0.031 seconds
[2024-04-29T17:58:12.584+0000] {processor.py:161} INFO - Started process (PID=14447) to work on /opt/airflow/dags/my_first_dag.py
[2024-04-29T17:58:12.593+0000] {processor.py:830} INFO - Processing file /opt/airflow/dags/my_first_dag.py for tasks to queue
[2024-04-29T17:58:12.595+0000] {logging_mixin.py:188} INFO - [2024-04-29T17:58:12.595+0000] {dagbag.py:540} INFO - Filling up the DagBag from /opt/airflow/dags/my_first_dag.py
[2024-04-29T17:58:12.602+0000] {logging_mixin.py:188} INFO - [2024-04-29T17:58:12.597+0000] {dagbag.py:350} ERROR - Failed to import: /opt/airflow/dags/my_first_dag.py
Traceback (most recent call last):
  File "/home/airflow/.local/lib/python3.8/site-packages/airflow/models/dagbag.py", line 346, in parse
    loader.exec_module(new_module)
  File "<frozen importlib._bootstrap_external>", line 843, in exec_module
  File "<frozen importlib._bootstrap>", line 219, in _call_with_frames_removed
  File "/opt/airflow/dags/my_first_dag.py", line 20, in <module>
    start_date=timezone.datatime(2024, 3, 23),
AttributeError: module 'airflow.utils.timezone' has no attribute 'datatime'
[2024-04-29T17:58:12.603+0000] {processor.py:842} WARNING - No viable dags retrieved from /opt/airflow/dags/my_first_dag.py
[2024-04-29T17:58:12.635+0000] {processor.py:183} INFO - Processing /opt/airflow/dags/my_first_dag.py took 0.062 seconds
[2024-04-29T17:58:19.477+0000] {processor.py:161} INFO - Started process (PID=14514) to work on /opt/airflow/dags/my_first_dag.py
[2024-04-29T17:58:19.477+0000] {processor.py:830} INFO - Processing file /opt/airflow/dags/my_first_dag.py for tasks to queue
[2024-04-29T17:58:19.478+0000] {logging_mixin.py:188} INFO - [2024-04-29T17:58:19.478+0000] {dagbag.py:540} INFO - Filling up the DagBag from /opt/airflow/dags/my_first_dag.py
[2024-04-29T17:58:19.481+0000] {logging_mixin.py:188} INFO - [2024-04-29T17:58:19.480+0000] {dagbag.py:350} ERROR - Failed to import: /opt/airflow/dags/my_first_dag.py
Traceback (most recent call last):
  File "/home/airflow/.local/lib/python3.8/site-packages/airflow/models/dagbag.py", line 346, in parse
    loader.exec_module(new_module)
  File "<frozen importlib._bootstrap_external>", line 843, in exec_module
  File "<frozen importlib._bootstrap>", line 219, in _call_with_frames_removed
  File "/opt/airflow/dags/my_first_dag.py", line 20, in <module>
    start_date=timezone.datatime(2024, 3, 23),
AttributeError: module 'airflow.utils.timezone' has no attribute 'datatime'
[2024-04-29T17:58:19.481+0000] {processor.py:842} WARNING - No viable dags retrieved from /opt/airflow/dags/my_first_dag.py
[2024-04-29T17:58:19.503+0000] {processor.py:183} INFO - Processing /opt/airflow/dags/my_first_dag.py took 0.029 seconds
[2024-04-29T17:58:26.519+0000] {processor.py:161} INFO - Started process (PID=14519) to work on /opt/airflow/dags/my_first_dag.py
[2024-04-29T17:58:26.520+0000] {processor.py:830} INFO - Processing file /opt/airflow/dags/my_first_dag.py for tasks to queue
[2024-04-29T17:58:26.521+0000] {logging_mixin.py:188} INFO - [2024-04-29T17:58:26.521+0000] {dagbag.py:540} INFO - Filling up the DagBag from /opt/airflow/dags/my_first_dag.py
[2024-04-29T17:58:26.524+0000] {logging_mixin.py:188} INFO - [2024-04-29T17:58:26.523+0000] {dagbag.py:350} ERROR - Failed to import: /opt/airflow/dags/my_first_dag.py
Traceback (most recent call last):
  File "/home/airflow/.local/lib/python3.8/site-packages/airflow/models/dagbag.py", line 346, in parse
    loader.exec_module(new_module)
  File "<frozen importlib._bootstrap_external>", line 839, in exec_module
  File "<frozen importlib._bootstrap_external>", line 976, in get_code
  File "<frozen importlib._bootstrap_external>", line 906, in source_to_code
  File "<frozen importlib._bootstrap>", line 219, in _call_with_frames_removed
  File "/opt/airflow/dags/my_first_dag.py", line 25
    my_fisrt_task = EmptyOperator(task_id=my_fisrt_task")
                                                        ^
SyntaxError: EOL while scanning string literal
[2024-04-29T17:58:26.524+0000] {processor.py:842} WARNING - No viable dags retrieved from /opt/airflow/dags/my_first_dag.py
[2024-04-29T17:58:26.553+0000] {processor.py:183} INFO - Processing /opt/airflow/dags/my_first_dag.py took 0.038 seconds
[2024-04-29T17:58:30.208+0000] {processor.py:161} INFO - Started process (PID=14579) to work on /opt/airflow/dags/my_first_dag.py
[2024-04-29T17:58:30.209+0000] {processor.py:830} INFO - Processing file /opt/airflow/dags/my_first_dag.py for tasks to queue
[2024-04-29T17:58:30.213+0000] {logging_mixin.py:188} INFO - [2024-04-29T17:58:30.213+0000] {dagbag.py:540} INFO - Filling up the DagBag from /opt/airflow/dags/my_first_dag.py
[2024-04-29T17:58:30.216+0000] {logging_mixin.py:188} INFO - [2024-04-29T17:58:30.216+0000] {dagbag.py:350} ERROR - Failed to import: /opt/airflow/dags/my_first_dag.py
Traceback (most recent call last):
  File "/home/airflow/.local/lib/python3.8/site-packages/airflow/models/dagbag.py", line 346, in parse
    loader.exec_module(new_module)
  File "<frozen importlib._bootstrap_external>", line 843, in exec_module
  File "<frozen importlib._bootstrap>", line 219, in _call_with_frames_removed
  File "/opt/airflow/dags/my_first_dag.py", line 20, in <module>
    start_date=timezone.datatime(2024, 3, 23),
AttributeError: module 'airflow.utils.timezone' has no attribute 'datatime'
[2024-04-29T17:58:30.217+0000] {processor.py:842} WARNING - No viable dags retrieved from /opt/airflow/dags/my_first_dag.py
[2024-04-29T17:58:30.249+0000] {processor.py:183} INFO - Processing /opt/airflow/dags/my_first_dag.py took 0.045 seconds
[2024-04-29T17:59:00.686+0000] {processor.py:161} INFO - Started process (PID=14831) to work on /opt/airflow/dags/my_first_dag.py
[2024-04-29T17:59:00.687+0000] {processor.py:830} INFO - Processing file /opt/airflow/dags/my_first_dag.py for tasks to queue
[2024-04-29T17:59:00.689+0000] {logging_mixin.py:188} INFO - [2024-04-29T17:59:00.688+0000] {dagbag.py:540} INFO - Filling up the DagBag from /opt/airflow/dags/my_first_dag.py
[2024-04-29T17:59:00.693+0000] {logging_mixin.py:188} INFO - [2024-04-29T17:59:00.692+0000] {dagbag.py:350} ERROR - Failed to import: /opt/airflow/dags/my_first_dag.py
Traceback (most recent call last):
  File "/home/airflow/.local/lib/python3.8/site-packages/airflow/models/dagbag.py", line 346, in parse
    loader.exec_module(new_module)
  File "<frozen importlib._bootstrap_external>", line 843, in exec_module
  File "<frozen importlib._bootstrap>", line 219, in _call_with_frames_removed
  File "/opt/airflow/dags/my_first_dag.py", line 21, in <module>
    start_date=timezone.datatime(2024, 3, 23),
AttributeError: module 'airflow.utils.timezone' has no attribute 'datatime'
[2024-04-29T17:59:00.694+0000] {processor.py:842} WARNING - No viable dags retrieved from /opt/airflow/dags/my_first_dag.py
[2024-04-29T17:59:00.721+0000] {processor.py:183} INFO - Processing /opt/airflow/dags/my_first_dag.py took 0.037 seconds
[2024-04-29T17:59:03.656+0000] {processor.py:161} INFO - Started process (PID=14887) to work on /opt/airflow/dags/my_first_dag.py
[2024-04-29T17:59:03.657+0000] {processor.py:830} INFO - Processing file /opt/airflow/dags/my_first_dag.py for tasks to queue
[2024-04-29T17:59:03.658+0000] {logging_mixin.py:188} INFO - [2024-04-29T17:59:03.657+0000] {dagbag.py:540} INFO - Filling up the DagBag from /opt/airflow/dags/my_first_dag.py
[2024-04-29T17:59:03.661+0000] {logging_mixin.py:188} INFO - [2024-04-29T17:59:03.660+0000] {dagbag.py:350} ERROR - Failed to import: /opt/airflow/dags/my_first_dag.py
Traceback (most recent call last):
  File "/home/airflow/.local/lib/python3.8/site-packages/airflow/models/dagbag.py", line 346, in parse
    loader.exec_module(new_module)
  File "<frozen importlib._bootstrap_external>", line 843, in exec_module
  File "<frozen importlib._bootstrap>", line 219, in _call_with_frames_removed
  File "/opt/airflow/dags/my_first_dag.py", line 2, in <module>
    from airflow.utils import timezon
ImportError: cannot import name 'timezon' from 'airflow.utils' (/home/airflow/.local/lib/python3.8/site-packages/airflow/utils/__init__.py)
[2024-04-29T17:59:03.661+0000] {processor.py:842} WARNING - No viable dags retrieved from /opt/airflow/dags/my_first_dag.py
[2024-04-29T17:59:03.683+0000] {processor.py:183} INFO - Processing /opt/airflow/dags/my_first_dag.py took 0.029 seconds
[2024-04-29T17:59:06.364+0000] {processor.py:161} INFO - Started process (PID=14935) to work on /opt/airflow/dags/my_first_dag.py
[2024-04-29T17:59:06.365+0000] {processor.py:830} INFO - Processing file /opt/airflow/dags/my_first_dag.py for tasks to queue
[2024-04-29T17:59:06.366+0000] {logging_mixin.py:188} INFO - [2024-04-29T17:59:06.365+0000] {dagbag.py:540} INFO - Filling up the DagBag from /opt/airflow/dags/my_first_dag.py
[2024-04-29T17:59:06.370+0000] {logging_mixin.py:188} INFO - [2024-04-29T17:59:06.370+0000] {dagbag.py:350} ERROR - Failed to import: /opt/airflow/dags/my_first_dag.py
Traceback (most recent call last):
  File "/home/airflow/.local/lib/python3.8/site-packages/airflow/models/dagbag.py", line 346, in parse
    loader.exec_module(new_module)
  File "<frozen importlib._bootstrap_external>", line 843, in exec_module
  File "<frozen importlib._bootstrap>", line 219, in _call_with_frames_removed
  File "/opt/airflow/dags/my_first_dag.py", line 21, in <module>
    start_date=timezone.datatime(2024, 3, 23),
AttributeError: module 'airflow.utils.timezone' has no attribute 'datatime'
[2024-04-29T17:59:06.371+0000] {processor.py:842} WARNING - No viable dags retrieved from /opt/airflow/dags/my_first_dag.py
[2024-04-29T17:59:06.396+0000] {processor.py:183} INFO - Processing /opt/airflow/dags/my_first_dag.py took 0.036 seconds
[2024-04-29T17:59:11.864+0000] {processor.py:161} INFO - Started process (PID=14977) to work on /opt/airflow/dags/my_first_dag.py
[2024-04-29T17:59:11.865+0000] {processor.py:830} INFO - Processing file /opt/airflow/dags/my_first_dag.py for tasks to queue
[2024-04-29T17:59:11.866+0000] {logging_mixin.py:188} INFO - [2024-04-29T17:59:11.866+0000] {dagbag.py:540} INFO - Filling up the DagBag from /opt/airflow/dags/my_first_dag.py
[2024-04-29T17:59:11.868+0000] {logging_mixin.py:188} INFO - [2024-04-29T17:59:11.867+0000] {dagbag.py:350} ERROR - Failed to import: /opt/airflow/dags/my_first_dag.py
Traceback (most recent call last):
  File "/home/airflow/.local/lib/python3.8/site-packages/airflow/models/dagbag.py", line 346, in parse
    loader.exec_module(new_module)
  File "<frozen importlib._bootstrap_external>", line 839, in exec_module
  File "<frozen importlib._bootstrap_external>", line 976, in get_code
  File "<frozen importlib._bootstrap_external>", line 906, in source_to_code
  File "<frozen importlib._bootstrap>", line 219, in _call_with_frames_removed
  File "/opt/airflow/dags/my_first_dag.py", line 2
    from airflow.ope
                   ^
SyntaxError: invalid syntax
[2024-04-29T17:59:11.868+0000] {processor.py:842} WARNING - No viable dags retrieved from /opt/airflow/dags/my_first_dag.py
[2024-04-29T17:59:11.889+0000] {processor.py:183} INFO - Processing /opt/airflow/dags/my_first_dag.py took 0.028 seconds
[2024-04-29T17:59:20.615+0000] {processor.py:161} INFO - Started process (PID=15044) to work on /opt/airflow/dags/my_first_dag.py
[2024-04-29T17:59:20.615+0000] {processor.py:830} INFO - Processing file /opt/airflow/dags/my_first_dag.py for tasks to queue
[2024-04-29T17:59:20.616+0000] {logging_mixin.py:188} INFO - [2024-04-29T17:59:20.616+0000] {dagbag.py:540} INFO - Filling up the DagBag from /opt/airflow/dags/my_first_dag.py
[2024-04-29T17:59:20.618+0000] {logging_mixin.py:188} INFO - [2024-04-29T17:59:20.618+0000] {dagbag.py:350} ERROR - Failed to import: /opt/airflow/dags/my_first_dag.py
Traceback (most recent call last):
  File "/home/airflow/.local/lib/python3.8/site-packages/airflow/models/dagbag.py", line 346, in parse
    loader.exec_module(new_module)
  File "<frozen importlib._bootstrap_external>", line 839, in exec_module
  File "<frozen importlib._bootstrap_external>", line 976, in get_code
  File "<frozen importlib._bootstrap_external>", line 906, in source_to_code
  File "<frozen importlib._bootstrap>", line 219, in _call_with_frames_removed
  File "/opt/airflow/dags/my_first_dag.py", line 2
    from airflow.operator.em
                           ^
SyntaxError: invalid syntax
[2024-04-29T17:59:20.619+0000] {processor.py:842} WARNING - No viable dags retrieved from /opt/airflow/dags/my_first_dag.py
[2024-04-29T17:59:20.643+0000] {processor.py:183} INFO - Processing /opt/airflow/dags/my_first_dag.py took 0.031 seconds
[2024-04-29T17:59:22.636+0000] {processor.py:161} INFO - Started process (PID=15049) to work on /opt/airflow/dags/my_first_dag.py
[2024-04-29T17:59:22.637+0000] {processor.py:830} INFO - Processing file /opt/airflow/dags/my_first_dag.py for tasks to queue
[2024-04-29T17:59:22.638+0000] {logging_mixin.py:188} INFO - [2024-04-29T17:59:22.638+0000] {dagbag.py:540} INFO - Filling up the DagBag from /opt/airflow/dags/my_first_dag.py
[2024-04-29T17:59:22.642+0000] {logging_mixin.py:188} INFO - [2024-04-29T17:59:22.641+0000] {dagbag.py:350} ERROR - Failed to import: /opt/airflow/dags/my_first_dag.py
Traceback (most recent call last):
  File "/home/airflow/.local/lib/python3.8/site-packages/airflow/models/dagbag.py", line 346, in parse
    loader.exec_module(new_module)
  File "<frozen importlib._bootstrap_external>", line 839, in exec_module
  File "<frozen importlib._bootstrap_external>", line 976, in get_code
  File "<frozen importlib._bootstrap_external>", line 906, in source_to_code
  File "<frozen importlib._bootstrap>", line 219, in _call_with_frames_removed
  File "/opt/airflow/dags/my_first_dag.py", line 2
    from airflow.operator.emtype
                               ^
SyntaxError: invalid syntax
[2024-04-29T17:59:22.642+0000] {processor.py:842} WARNING - No viable dags retrieved from /opt/airflow/dags/my_first_dag.py
[2024-04-29T17:59:22.667+0000] {processor.py:183} INFO - Processing /opt/airflow/dags/my_first_dag.py took 0.033 seconds
[2024-04-29T17:59:28.903+0000] {processor.py:161} INFO - Started process (PID=15069) to work on /opt/airflow/dags/my_first_dag.py
[2024-04-29T17:59:28.904+0000] {processor.py:830} INFO - Processing file /opt/airflow/dags/my_first_dag.py for tasks to queue
[2024-04-29T17:59:28.906+0000] {logging_mixin.py:188} INFO - [2024-04-29T17:59:28.905+0000] {dagbag.py:540} INFO - Filling up the DagBag from /opt/airflow/dags/my_first_dag.py
[2024-04-29T17:59:28.910+0000] {logging_mixin.py:188} INFO - [2024-04-29T17:59:28.908+0000] {dagbag.py:350} ERROR - Failed to import: /opt/airflow/dags/my_first_dag.py
Traceback (most recent call last):
  File "/home/airflow/.local/lib/python3.8/site-packages/airflow/models/dagbag.py", line 346, in parse
    loader.exec_module(new_module)
  File "<frozen importlib._bootstrap_external>", line 839, in exec_module
  File "<frozen importlib._bootstrap_external>", line 976, in get_code
  File "<frozen importlib._bootstrap_external>", line 906, in source_to_code
  File "<frozen importlib._bootstrap>", line 219, in _call_with_frames_removed
  File "/opt/airflow/dags/my_first_dag.py", line 2
    from airflow.operator.empty import
                                      ^
SyntaxError: invalid syntax
[2024-04-29T17:59:28.910+0000] {processor.py:842} WARNING - No viable dags retrieved from /opt/airflow/dags/my_first_dag.py
[2024-04-29T17:59:28.963+0000] {processor.py:183} INFO - Processing /opt/airflow/dags/my_first_dag.py took 0.064 seconds
[2024-04-29T17:59:32.819+0000] {processor.py:161} INFO - Started process (PID=15124) to work on /opt/airflow/dags/my_first_dag.py
[2024-04-29T17:59:32.821+0000] {processor.py:830} INFO - Processing file /opt/airflow/dags/my_first_dag.py for tasks to queue
[2024-04-29T17:59:32.822+0000] {logging_mixin.py:188} INFO - [2024-04-29T17:59:32.822+0000] {dagbag.py:540} INFO - Filling up the DagBag from /opt/airflow/dags/my_first_dag.py
[2024-04-29T17:59:32.825+0000] {logging_mixin.py:188} INFO - [2024-04-29T17:59:32.824+0000] {dagbag.py:350} ERROR - Failed to import: /opt/airflow/dags/my_first_dag.py
Traceback (most recent call last):
  File "/home/airflow/.local/lib/python3.8/site-packages/airflow/models/dagbag.py", line 346, in parse
    loader.exec_module(new_module)
  File "<frozen importlib._bootstrap_external>", line 839, in exec_module
  File "<frozen importlib._bootstrap_external>", line 976, in get_code
  File "<frozen importlib._bootstrap_external>", line 906, in source_to_code
  File "<frozen importlib._bootstrap>", line 219, in _call_with_frames_removed
  File "/opt/airflow/dags/my_first_dag.py", line 2
    from airflow.operators.empty import
                                       ^
SyntaxError: invalid syntax
[2024-04-29T17:59:32.825+0000] {processor.py:842} WARNING - No viable dags retrieved from /opt/airflow/dags/my_first_dag.py
[2024-04-29T17:59:32.852+0000] {processor.py:183} INFO - Processing /opt/airflow/dags/my_first_dag.py took 0.037 seconds
[2024-04-29T17:59:37.502+0000] {processor.py:161} INFO - Started process (PID=15215) to work on /opt/airflow/dags/my_first_dag.py
[2024-04-29T17:59:37.503+0000] {processor.py:830} INFO - Processing file /opt/airflow/dags/my_first_dag.py for tasks to queue
[2024-04-29T17:59:37.504+0000] {logging_mixin.py:188} INFO - [2024-04-29T17:59:37.504+0000] {dagbag.py:540} INFO - Filling up the DagBag from /opt/airflow/dags/my_first_dag.py
[2024-04-29T17:59:37.507+0000] {logging_mixin.py:188} INFO - [2024-04-29T17:59:37.506+0000] {dagbag.py:350} ERROR - Failed to import: /opt/airflow/dags/my_first_dag.py
Traceback (most recent call last):
  File "/home/airflow/.local/lib/python3.8/site-packages/airflow/models/dagbag.py", line 346, in parse
    loader.exec_module(new_module)
  File "<frozen importlib._bootstrap_external>", line 843, in exec_module
  File "<frozen importlib._bootstrap>", line 219, in _call_with_frames_removed
  File "/opt/airflow/dags/my_first_dag.py", line 21, in <module>
    start_date=timezone.datatime(2024, 3, 23),
AttributeError: module 'airflow.utils.timezone' has no attribute 'datatime'
[2024-04-29T17:59:37.507+0000] {processor.py:842} WARNING - No viable dags retrieved from /opt/airflow/dags/my_first_dag.py
[2024-04-29T17:59:37.529+0000] {processor.py:183} INFO - Processing /opt/airflow/dags/my_first_dag.py took 0.029 seconds
[2024-04-29T18:00:07.832+0000] {processor.py:161} INFO - Started process (PID=15467) to work on /opt/airflow/dags/my_first_dag.py
[2024-04-29T18:00:07.834+0000] {processor.py:830} INFO - Processing file /opt/airflow/dags/my_first_dag.py for tasks to queue
[2024-04-29T18:00:07.835+0000] {logging_mixin.py:188} INFO - [2024-04-29T18:00:07.834+0000] {dagbag.py:540} INFO - Filling up the DagBag from /opt/airflow/dags/my_first_dag.py
[2024-04-29T18:00:07.838+0000] {logging_mixin.py:188} INFO - [2024-04-29T18:00:07.837+0000] {dagbag.py:350} ERROR - Failed to import: /opt/airflow/dags/my_first_dag.py
Traceback (most recent call last):
  File "/home/airflow/.local/lib/python3.8/site-packages/airflow/models/dagbag.py", line 346, in parse
    loader.exec_module(new_module)
  File "<frozen importlib._bootstrap_external>", line 843, in exec_module
  File "<frozen importlib._bootstrap>", line 219, in _call_with_frames_removed
  File "/opt/airflow/dags/my_first_dag.py", line 21, in <module>
    start_date=timezone.datatime(2024, 3, 23),
AttributeError: module 'airflow.utils.timezone' has no attribute 'datatime'
[2024-04-29T18:00:07.838+0000] {processor.py:842} WARNING - No viable dags retrieved from /opt/airflow/dags/my_first_dag.py
[2024-04-29T18:00:07.871+0000] {processor.py:183} INFO - Processing /opt/airflow/dags/my_first_dag.py took 0.043 seconds
[2024-04-29T18:00:13.435+0000] {processor.py:161} INFO - Started process (PID=15507) to work on /opt/airflow/dags/my_first_dag.py
[2024-04-29T18:00:13.436+0000] {processor.py:830} INFO - Processing file /opt/airflow/dags/my_first_dag.py for tasks to queue
[2024-04-29T18:00:13.436+0000] {logging_mixin.py:188} INFO - [2024-04-29T18:00:13.436+0000] {dagbag.py:540} INFO - Filling up the DagBag from /opt/airflow/dags/my_first_dag.py
[2024-04-29T18:00:13.439+0000] {logging_mixin.py:188} INFO - [2024-04-29T18:00:13.439+0000] {dagbag.py:350} ERROR - Failed to import: /opt/airflow/dags/my_first_dag.py
Traceback (most recent call last):
  File "/home/airflow/.local/lib/python3.8/site-packages/airflow/models/dagbag.py", line 346, in parse
    loader.exec_module(new_module)
  File "<frozen importlib._bootstrap_external>", line 843, in exec_module
  File "<frozen importlib._bootstrap>", line 219, in _call_with_frames_removed
  File "/opt/airflow/dags/my_first_dag.py", line 21, in <module>
    start_date=timezone.datatime(2024, 3, 23),
AttributeError: module 'airflow.utils.timezone' has no attribute 'datatime'
[2024-04-29T18:00:13.440+0000] {processor.py:842} WARNING - No viable dags retrieved from /opt/airflow/dags/my_first_dag.py
[2024-04-29T18:00:13.463+0000] {processor.py:183} INFO - Processing /opt/airflow/dags/my_first_dag.py took 0.031 seconds
[2024-04-29T18:00:19.135+0000] {processor.py:161} INFO - Started process (PID=15573) to work on /opt/airflow/dags/my_first_dag.py
[2024-04-29T18:00:19.136+0000] {processor.py:830} INFO - Processing file /opt/airflow/dags/my_first_dag.py for tasks to queue
[2024-04-29T18:00:19.137+0000] {logging_mixin.py:188} INFO - [2024-04-29T18:00:19.137+0000] {dagbag.py:540} INFO - Filling up the DagBag from /opt/airflow/dags/my_first_dag.py
[2024-04-29T18:00:19.140+0000] {logging_mixin.py:188} INFO - [2024-04-29T18:00:19.139+0000] {dagbag.py:350} ERROR - Failed to import: /opt/airflow/dags/my_first_dag.py
Traceback (most recent call last):
  File "/home/airflow/.local/lib/python3.8/site-packages/airflow/models/dagbag.py", line 346, in parse
    loader.exec_module(new_module)
  File "<frozen importlib._bootstrap_external>", line 843, in exec_module
  File "<frozen importlib._bootstrap>", line 219, in _call_with_frames_removed
  File "/opt/airflow/dags/my_first_dag.py", line 21, in <module>
    start_date=timezone.datatime(2024, 3, 23),
AttributeError: module 'airflow.utils.timezone' has no attribute 'datatime'
[2024-04-29T18:00:19.140+0000] {processor.py:842} WARNING - No viable dags retrieved from /opt/airflow/dags/my_first_dag.py
[2024-04-29T18:00:19.162+0000] {processor.py:183} INFO - Processing /opt/airflow/dags/my_first_dag.py took 0.029 seconds
[2024-04-29T18:00:23.163+0000] {processor.py:161} INFO - Started process (PID=15578) to work on /opt/airflow/dags/my_first_dag.py
[2024-04-29T18:00:23.164+0000] {processor.py:830} INFO - Processing file /opt/airflow/dags/my_first_dag.py for tasks to queue
[2024-04-29T18:00:23.164+0000] {logging_mixin.py:188} INFO - [2024-04-29T18:00:23.164+0000] {dagbag.py:540} INFO - Filling up the DagBag from /opt/airflow/dags/my_first_dag.py
[2024-04-29T18:00:23.168+0000] {logging_mixin.py:188} INFO - [2024-04-29T18:00:23.167+0000] {dagbag.py:350} ERROR - Failed to import: /opt/airflow/dags/my_first_dag.py
Traceback (most recent call last):
  File "/home/airflow/.local/lib/python3.8/site-packages/airflow/models/dagbag.py", line 346, in parse
    loader.exec_module(new_module)
  File "<frozen importlib._bootstrap_external>", line 843, in exec_module
  File "<frozen importlib._bootstrap>", line 219, in _call_with_frames_removed
  File "/opt/airflow/dags/my_first_dag.py", line 21, in <module>
    start_date=timezone.datatime(2024, 3, 23),
AttributeError: module 'airflow.utils.timezone' has no attribute 'datatime'
[2024-04-29T18:00:23.168+0000] {processor.py:842} WARNING - No viable dags retrieved from /opt/airflow/dags/my_first_dag.py
[2024-04-29T18:00:23.189+0000] {processor.py:183} INFO - Processing /opt/airflow/dags/my_first_dag.py took 0.029 seconds
[2024-04-29T18:00:27.216+0000] {processor.py:161} INFO - Started process (PID=15583) to work on /opt/airflow/dags/my_first_dag.py
[2024-04-29T18:00:27.217+0000] {processor.py:830} INFO - Processing file /opt/airflow/dags/my_first_dag.py for tasks to queue
[2024-04-29T18:00:27.217+0000] {logging_mixin.py:188} INFO - [2024-04-29T18:00:27.217+0000] {dagbag.py:540} INFO - Filling up the DagBag from /opt/airflow/dags/my_first_dag.py
[2024-04-29T18:00:27.220+0000] {logging_mixin.py:188} INFO - [2024-04-29T18:00:27.219+0000] {dagbag.py:350} ERROR - Failed to import: /opt/airflow/dags/my_first_dag.py
Traceback (most recent call last):
  File "/home/airflow/.local/lib/python3.8/site-packages/airflow/models/dagbag.py", line 346, in parse
    loader.exec_module(new_module)
  File "<frozen importlib._bootstrap_external>", line 843, in exec_module
  File "<frozen importlib._bootstrap>", line 219, in _call_with_frames_removed
  File "/opt/airflow/dags/my_first_dag.py", line 21, in <module>
    start_date=timezone.datatime(2024, 3, 23),
AttributeError: module 'airflow.utils.timezone' has no attribute 'datatime'
[2024-04-29T18:00:27.220+0000] {processor.py:842} WARNING - No viable dags retrieved from /opt/airflow/dags/my_first_dag.py
[2024-04-29T18:00:27.245+0000] {processor.py:183} INFO - Processing /opt/airflow/dags/my_first_dag.py took 0.032 seconds
[2024-04-29T18:00:37.326+0000] {processor.py:161} INFO - Started process (PID=15724) to work on /opt/airflow/dags/my_first_dag.py
[2024-04-29T18:00:37.329+0000] {processor.py:830} INFO - Processing file /opt/airflow/dags/my_first_dag.py for tasks to queue
[2024-04-29T18:00:37.329+0000] {logging_mixin.py:188} INFO - [2024-04-29T18:00:37.329+0000] {dagbag.py:540} INFO - Filling up the DagBag from /opt/airflow/dags/my_first_dag.py
[2024-04-29T18:00:37.333+0000] {logging_mixin.py:188} INFO - [2024-04-29T18:00:37.332+0000] {dagbag.py:350} ERROR - Failed to import: /opt/airflow/dags/my_first_dag.py
Traceback (most recent call last):
  File "/home/airflow/.local/lib/python3.8/site-packages/airflow/models/dagbag.py", line 346, in parse
    loader.exec_module(new_module)
  File "<frozen importlib._bootstrap_external>", line 843, in exec_module
  File "<frozen importlib._bootstrap>", line 219, in _call_with_frames_removed
  File "/opt/airflow/dags/my_first_dag.py", line 21, in <module>
    start_date=timezone.datatime(2024, 3, 23),
AttributeError: module 'airflow.utils.timezone' has no attribute 'datatime'
[2024-04-29T18:00:37.333+0000] {processor.py:842} WARNING - No viable dags retrieved from /opt/airflow/dags/my_first_dag.py
[2024-04-29T18:00:37.358+0000] {processor.py:183} INFO - Processing /opt/airflow/dags/my_first_dag.py took 0.035 seconds
[2024-04-29T18:00:43.127+0000] {processor.py:161} INFO - Started process (PID=15779) to work on /opt/airflow/dags/my_first_dag.py
[2024-04-29T18:00:43.128+0000] {processor.py:830} INFO - Processing file /opt/airflow/dags/my_first_dag.py for tasks to queue
[2024-04-29T18:00:43.129+0000] {logging_mixin.py:188} INFO - [2024-04-29T18:00:43.128+0000] {dagbag.py:540} INFO - Filling up the DagBag from /opt/airflow/dags/my_first_dag.py
[2024-04-29T18:00:43.132+0000] {logging_mixin.py:188} INFO - [2024-04-29T18:00:43.132+0000] {dagbag.py:350} ERROR - Failed to import: /opt/airflow/dags/my_first_dag.py
Traceback (most recent call last):
  File "/home/airflow/.local/lib/python3.8/site-packages/airflow/models/dagbag.py", line 346, in parse
    loader.exec_module(new_module)
  File "<frozen importlib._bootstrap_external>", line 843, in exec_module
  File "<frozen importlib._bootstrap>", line 219, in _call_with_frames_removed
  File "/opt/airflow/dags/my_first_dag.py", line 21, in <module>
    start_date=timezone.datatime(2024, 3, 23),
AttributeError: module 'airflow.utils.timezone' has no attribute 'datatime'
[2024-04-29T18:00:43.133+0000] {processor.py:842} WARNING - No viable dags retrieved from /opt/airflow/dags/my_first_dag.py
[2024-04-29T18:00:43.154+0000] {processor.py:183} INFO - Processing /opt/airflow/dags/my_first_dag.py took 0.030 seconds
[2024-04-29T18:00:48.205+0000] {processor.py:161} INFO - Started process (PID=15839) to work on /opt/airflow/dags/my_first_dag.py
[2024-04-29T18:00:48.206+0000] {processor.py:830} INFO - Processing file /opt/airflow/dags/my_first_dag.py for tasks to queue
[2024-04-29T18:00:48.207+0000] {logging_mixin.py:188} INFO - [2024-04-29T18:00:48.207+0000] {dagbag.py:540} INFO - Filling up the DagBag from /opt/airflow/dags/my_first_dag.py
[2024-04-29T18:00:48.211+0000] {logging_mixin.py:188} INFO - [2024-04-29T18:00:48.211+0000] {dagbag.py:350} ERROR - Failed to import: /opt/airflow/dags/my_first_dag.py
Traceback (most recent call last):
  File "/home/airflow/.local/lib/python3.8/site-packages/airflow/models/dagbag.py", line 346, in parse
    loader.exec_module(new_module)
  File "<frozen importlib._bootstrap_external>", line 843, in exec_module
  File "<frozen importlib._bootstrap>", line 219, in _call_with_frames_removed
  File "/opt/airflow/dags/my_first_dag.py", line 21, in <module>
    start_date=timezone.datatime(2024, 3, 23),
AttributeError: module 'airflow.utils.timezone' has no attribute 'datatime'
[2024-04-29T18:00:48.212+0000] {processor.py:842} WARNING - No viable dags retrieved from /opt/airflow/dags/my_first_dag.py
[2024-04-29T18:00:48.241+0000] {processor.py:183} INFO - Processing /opt/airflow/dags/my_first_dag.py took 0.041 seconds
[2024-04-29T18:00:55.247+0000] {processor.py:161} INFO - Started process (PID=15850) to work on /opt/airflow/dags/my_first_dag.py
[2024-04-29T18:00:55.247+0000] {processor.py:830} INFO - Processing file /opt/airflow/dags/my_first_dag.py for tasks to queue
[2024-04-29T18:00:55.248+0000] {logging_mixin.py:188} INFO - [2024-04-29T18:00:55.248+0000] {dagbag.py:540} INFO - Filling up the DagBag from /opt/airflow/dags/my_first_dag.py
[2024-04-29T18:00:55.251+0000] {logging_mixin.py:188} INFO - [2024-04-29T18:00:55.250+0000] {dagbag.py:350} ERROR - Failed to import: /opt/airflow/dags/my_first_dag.py
Traceback (most recent call last):
  File "/home/airflow/.local/lib/python3.8/site-packages/airflow/models/dagbag.py", line 346, in parse
    loader.exec_module(new_module)
  File "<frozen importlib._bootstrap_external>", line 843, in exec_module
  File "<frozen importlib._bootstrap>", line 219, in _call_with_frames_removed
  File "/opt/airflow/dags/my_first_dag.py", line 21, in <module>
    start_date=timezone.datatime(2024, 3, 23),
AttributeError: module 'airflow.utils.timezone' has no attribute 'datatime'
[2024-04-29T18:00:55.251+0000] {processor.py:842} WARNING - No viable dags retrieved from /opt/airflow/dags/my_first_dag.py
[2024-04-29T18:00:55.272+0000] {processor.py:183} INFO - Processing /opt/airflow/dags/my_first_dag.py took 0.029 seconds
[2024-04-29T18:01:04.029+0000] {processor.py:161} INFO - Started process (PID=15910) to work on /opt/airflow/dags/my_first_dag.py
[2024-04-29T18:01:04.034+0000] {processor.py:830} INFO - Processing file /opt/airflow/dags/my_first_dag.py for tasks to queue
[2024-04-29T18:01:04.035+0000] {logging_mixin.py:188} INFO - [2024-04-29T18:01:04.034+0000] {dagbag.py:540} INFO - Filling up the DagBag from /opt/airflow/dags/my_first_dag.py
[2024-04-29T18:01:04.038+0000] {logging_mixin.py:188} INFO - [2024-04-29T18:01:04.037+0000] {dagbag.py:350} ERROR - Failed to import: /opt/airflow/dags/my_first_dag.py
Traceback (most recent call last):
  File "/home/airflow/.local/lib/python3.8/site-packages/airflow/models/dagbag.py", line 346, in parse
    loader.exec_module(new_module)
  File "<frozen importlib._bootstrap_external>", line 843, in exec_module
  File "<frozen importlib._bootstrap>", line 219, in _call_with_frames_removed
  File "/opt/airflow/dags/my_first_dag.py", line 21, in <module>
    start_date=timezone.datatime(2024, 3, 23),
AttributeError: module 'airflow.utils.timezone' has no attribute 'datatime'
[2024-04-29T18:01:04.039+0000] {processor.py:842} WARNING - No viable dags retrieved from /opt/airflow/dags/my_first_dag.py
[2024-04-29T18:01:04.066+0000] {processor.py:183} INFO - Processing /opt/airflow/dags/my_first_dag.py took 0.042 seconds
[2024-04-29T18:01:11.828+0000] {processor.py:161} INFO - Started process (PID=16036) to work on /opt/airflow/dags/my_first_dag.py
[2024-04-29T18:01:11.829+0000] {processor.py:830} INFO - Processing file /opt/airflow/dags/my_first_dag.py for tasks to queue
[2024-04-29T18:01:11.830+0000] {logging_mixin.py:188} INFO - [2024-04-29T18:01:11.830+0000] {dagbag.py:540} INFO - Filling up the DagBag from /opt/airflow/dags/my_first_dag.py
[2024-04-29T18:01:11.832+0000] {logging_mixin.py:188} INFO - [2024-04-29T18:01:11.831+0000] {dagbag.py:350} ERROR - Failed to import: /opt/airflow/dags/my_first_dag.py
Traceback (most recent call last):
  File "/home/airflow/.local/lib/python3.8/site-packages/airflow/models/dagbag.py", line 346, in parse
    loader.exec_module(new_module)
  File "<frozen importlib._bootstrap_external>", line 839, in exec_module
  File "<frozen importlib._bootstrap_external>", line 976, in get_code
  File "<frozen importlib._bootstrap_external>", line 906, in source_to_code
  File "<frozen importlib._bootstrap>", line 219, in _call_with_frames_removed
  File "/opt/airflow/dags/my_first_dag.py", line 30
    my_first_task >>
                    ^
SyntaxError: invalid syntax
[2024-04-29T18:01:11.832+0000] {processor.py:842} WARNING - No viable dags retrieved from /opt/airflow/dags/my_first_dag.py
[2024-04-29T18:01:11.855+0000] {processor.py:183} INFO - Processing /opt/airflow/dags/my_first_dag.py took 0.029 seconds
[2024-04-29T18:01:16.044+0000] {processor.py:161} INFO - Started process (PID=16051) to work on /opt/airflow/dags/my_first_dag.py
[2024-04-29T18:01:16.045+0000] {processor.py:830} INFO - Processing file /opt/airflow/dags/my_first_dag.py for tasks to queue
[2024-04-29T18:01:16.047+0000] {logging_mixin.py:188} INFO - [2024-04-29T18:01:16.046+0000] {dagbag.py:540} INFO - Filling up the DagBag from /opt/airflow/dags/my_first_dag.py
[2024-04-29T18:01:16.058+0000] {logging_mixin.py:188} INFO - [2024-04-29T18:01:16.057+0000] {dagbag.py:350} ERROR - Failed to import: /opt/airflow/dags/my_first_dag.py
Traceback (most recent call last):
  File "/home/airflow/.local/lib/python3.8/site-packages/airflow/models/dagbag.py", line 346, in parse
    loader.exec_module(new_module)
  File "<frozen importlib._bootstrap_external>", line 843, in exec_module
  File "<frozen importlib._bootstrap>", line 219, in _call_with_frames_removed
  File "/opt/airflow/dags/my_first_dag.py", line 21, in <module>
    start_date=timezone.datatime(2024, 3, 23),
AttributeError: module 'airflow.utils.timezone' has no attribute 'datatime'
[2024-04-29T18:01:16.060+0000] {processor.py:842} WARNING - No viable dags retrieved from /opt/airflow/dags/my_first_dag.py
[2024-04-29T18:01:16.101+0000] {processor.py:183} INFO - Processing /opt/airflow/dags/my_first_dag.py took 0.060 seconds
[2024-04-29T18:01:17.791+0000] {processor.py:161} INFO - Started process (PID=16101) to work on /opt/airflow/dags/my_first_dag.py
[2024-04-29T18:01:17.792+0000] {processor.py:830} INFO - Processing file /opt/airflow/dags/my_first_dag.py for tasks to queue
[2024-04-29T18:01:17.793+0000] {logging_mixin.py:188} INFO - [2024-04-29T18:01:17.792+0000] {dagbag.py:540} INFO - Filling up the DagBag from /opt/airflow/dags/my_first_dag.py
[2024-04-29T18:01:17.800+0000] {logging_mixin.py:188} INFO - [2024-04-29T18:01:17.799+0000] {dagbag.py:350} ERROR - Failed to import: /opt/airflow/dags/my_first_dag.py
Traceback (most recent call last):
  File "/home/airflow/.local/lib/python3.8/site-packages/airflow/models/dagbag.py", line 346, in parse
    loader.exec_module(new_module)
  File "<frozen importlib._bootstrap_external>", line 843, in exec_module
  File "<frozen importlib._bootstrap>", line 219, in _call_with_frames_removed
  File "/opt/airflow/dags/my_first_dag.py", line 21, in <module>
    start_date=timezone.datatime(2024, 3, 23),
AttributeError: module 'airflow.utils.timezone' has no attribute 'datatime'
[2024-04-29T18:01:17.801+0000] {processor.py:842} WARNING - No viable dags retrieved from /opt/airflow/dags/my_first_dag.py
[2024-04-29T18:01:17.855+0000] {processor.py:183} INFO - Processing /opt/airflow/dags/my_first_dag.py took 0.068 seconds
[2024-04-29T18:01:23.336+0000] {processor.py:161} INFO - Started process (PID=16122) to work on /opt/airflow/dags/my_first_dag.py
[2024-04-29T18:01:23.337+0000] {processor.py:830} INFO - Processing file /opt/airflow/dags/my_first_dag.py for tasks to queue
[2024-04-29T18:01:23.338+0000] {logging_mixin.py:188} INFO - [2024-04-29T18:01:23.337+0000] {dagbag.py:540} INFO - Filling up the DagBag from /opt/airflow/dags/my_first_dag.py
[2024-04-29T18:01:23.340+0000] {logging_mixin.py:188} INFO - [2024-04-29T18:01:23.340+0000] {dagbag.py:350} ERROR - Failed to import: /opt/airflow/dags/my_first_dag.py
Traceback (most recent call last):
  File "/home/airflow/.local/lib/python3.8/site-packages/airflow/models/dagbag.py", line 346, in parse
    loader.exec_module(new_module)
  File "<frozen importlib._bootstrap_external>", line 843, in exec_module
  File "<frozen importlib._bootstrap>", line 219, in _call_with_frames_removed
  File "/opt/airflow/dags/my_first_dag.py", line 21, in <module>
    start_date=timezone.datatime(2024, 3, 23),
AttributeError: module 'airflow.utils.timezone' has no attribute 'datatime'
[2024-04-29T18:01:23.341+0000] {processor.py:842} WARNING - No viable dags retrieved from /opt/airflow/dags/my_first_dag.py
[2024-04-29T18:01:23.363+0000] {processor.py:183} INFO - Processing /opt/airflow/dags/my_first_dag.py took 0.029 seconds
[2024-04-29T18:01:30.370+0000] {processor.py:161} INFO - Started process (PID=16127) to work on /opt/airflow/dags/my_first_dag.py
[2024-04-29T18:01:30.371+0000] {processor.py:830} INFO - Processing file /opt/airflow/dags/my_first_dag.py for tasks to queue
[2024-04-29T18:01:30.372+0000] {logging_mixin.py:188} INFO - [2024-04-29T18:01:30.371+0000] {dagbag.py:540} INFO - Filling up the DagBag from /opt/airflow/dags/my_first_dag.py
[2024-04-29T18:01:30.375+0000] {logging_mixin.py:188} INFO - [2024-04-29T18:01:30.374+0000] {dagbag.py:350} ERROR - Failed to import: /opt/airflow/dags/my_first_dag.py
Traceback (most recent call last):
  File "/home/airflow/.local/lib/python3.8/site-packages/airflow/models/dagbag.py", line 346, in parse
    loader.exec_module(new_module)
  File "<frozen importlib._bootstrap_external>", line 843, in exec_module
  File "<frozen importlib._bootstrap>", line 219, in _call_with_frames_removed
  File "/opt/airflow/dags/my_first_dag.py", line 21, in <module>
    start_date=timezone.datatime(2024, 3, 23),
AttributeError: module 'airflow.utils.timezone' has no attribute 'datatime'
[2024-04-29T18:01:30.375+0000] {processor.py:842} WARNING - No viable dags retrieved from /opt/airflow/dags/my_first_dag.py
[2024-04-29T18:01:30.417+0000] {processor.py:183} INFO - Processing /opt/airflow/dags/my_first_dag.py took 0.050 seconds
[2024-04-29T18:01:32.220+0000] {processor.py:161} INFO - Started process (PID=16177) to work on /opt/airflow/dags/my_first_dag.py
[2024-04-29T18:01:32.221+0000] {processor.py:830} INFO - Processing file /opt/airflow/dags/my_first_dag.py for tasks to queue
[2024-04-29T18:01:32.221+0000] {logging_mixin.py:188} INFO - [2024-04-29T18:01:32.221+0000] {dagbag.py:540} INFO - Filling up the DagBag from /opt/airflow/dags/my_first_dag.py
[2024-04-29T18:01:32.224+0000] {logging_mixin.py:188} INFO - [2024-04-29T18:01:32.223+0000] {dagbag.py:350} ERROR - Failed to import: /opt/airflow/dags/my_first_dag.py
Traceback (most recent call last):
  File "/home/airflow/.local/lib/python3.8/site-packages/airflow/models/dagbag.py", line 346, in parse
    loader.exec_module(new_module)
  File "<frozen importlib._bootstrap_external>", line 843, in exec_module
  File "<frozen importlib._bootstrap>", line 219, in _call_with_frames_removed
  File "/opt/airflow/dags/my_first_dag.py", line 21, in <module>
    start_date=timezone.datatime(2024, 3, 23),
AttributeError: module 'airflow.utils.timezone' has no attribute 'datatime'
[2024-04-29T18:01:32.224+0000] {processor.py:842} WARNING - No viable dags retrieved from /opt/airflow/dags/my_first_dag.py
[2024-04-29T18:01:32.247+0000] {processor.py:183} INFO - Processing /opt/airflow/dags/my_first_dag.py took 0.030 seconds
[2024-04-29T18:02:02.503+0000] {processor.py:161} INFO - Started process (PID=16429) to work on /opt/airflow/dags/my_first_dag.py
[2024-04-29T18:02:02.503+0000] {processor.py:830} INFO - Processing file /opt/airflow/dags/my_first_dag.py for tasks to queue
[2024-04-29T18:02:02.504+0000] {logging_mixin.py:188} INFO - [2024-04-29T18:02:02.504+0000] {dagbag.py:540} INFO - Filling up the DagBag from /opt/airflow/dags/my_first_dag.py
[2024-04-29T18:02:02.506+0000] {logging_mixin.py:188} INFO - [2024-04-29T18:02:02.506+0000] {dagbag.py:350} ERROR - Failed to import: /opt/airflow/dags/my_first_dag.py
Traceback (most recent call last):
  File "/home/airflow/.local/lib/python3.8/site-packages/airflow/models/dagbag.py", line 346, in parse
    loader.exec_module(new_module)
  File "<frozen importlib._bootstrap_external>", line 843, in exec_module
  File "<frozen importlib._bootstrap>", line 219, in _call_with_frames_removed
  File "/opt/airflow/dags/my_first_dag.py", line 21, in <module>
    start_date=timezone.datatime(2024, 3, 23),
AttributeError: module 'airflow.utils.timezone' has no attribute 'datatime'
[2024-04-29T18:02:02.507+0000] {processor.py:842} WARNING - No viable dags retrieved from /opt/airflow/dags/my_first_dag.py
[2024-04-29T18:02:02.528+0000] {processor.py:183} INFO - Processing /opt/airflow/dags/my_first_dag.py took 0.028 seconds
[2024-04-29T18:02:33.463+0000] {processor.py:161} INFO - Started process (PID=16681) to work on /opt/airflow/dags/my_first_dag.py
[2024-04-29T18:02:33.464+0000] {processor.py:830} INFO - Processing file /opt/airflow/dags/my_first_dag.py for tasks to queue
[2024-04-29T18:02:33.465+0000] {logging_mixin.py:188} INFO - [2024-04-29T18:02:33.464+0000] {dagbag.py:540} INFO - Filling up the DagBag from /opt/airflow/dags/my_first_dag.py
[2024-04-29T18:02:33.468+0000] {logging_mixin.py:188} INFO - [2024-04-29T18:02:33.466+0000] {dagbag.py:350} ERROR - Failed to import: /opt/airflow/dags/my_first_dag.py
Traceback (most recent call last):
  File "/home/airflow/.local/lib/python3.8/site-packages/airflow/models/dagbag.py", line 346, in parse
    loader.exec_module(new_module)
  File "<frozen importlib._bootstrap_external>", line 843, in exec_module
  File "<frozen importlib._bootstrap>", line 219, in _call_with_frames_removed
  File "/opt/airflow/dags/my_first_dag.py", line 21, in <module>
    start_date=timezone.datatime(2024, 3, 23),
AttributeError: module 'airflow.utils.timezone' has no attribute 'datatime'
[2024-04-29T18:02:33.468+0000] {processor.py:842} WARNING - No viable dags retrieved from /opt/airflow/dags/my_first_dag.py
[2024-04-29T18:02:33.503+0000] {processor.py:183} INFO - Processing /opt/airflow/dags/my_first_dag.py took 0.043 seconds
[2024-04-29T18:02:50.600+0000] {processor.py:161} INFO - Started process (PID=16884) to work on /opt/airflow/dags/my_first_dag.py
[2024-04-29T18:02:50.604+0000] {processor.py:830} INFO - Processing file /opt/airflow/dags/my_first_dag.py for tasks to queue
[2024-04-29T18:02:50.606+0000] {logging_mixin.py:188} INFO - [2024-04-29T18:02:50.605+0000] {dagbag.py:540} INFO - Filling up the DagBag from /opt/airflow/dags/my_first_dag.py
[2024-04-29T18:02:50.611+0000] {logging_mixin.py:188} INFO - [2024-04-29T18:02:50.610+0000] {dagbag.py:350} ERROR - Failed to import: /opt/airflow/dags/my_first_dag.py
Traceback (most recent call last):
  File "/home/airflow/.local/lib/python3.8/site-packages/airflow/models/dagbag.py", line 346, in parse
    loader.exec_module(new_module)
  File "<frozen importlib._bootstrap_external>", line 843, in exec_module
  File "<frozen importlib._bootstrap>", line 219, in _call_with_frames_removed
  File "/opt/airflow/dags/my_first_dag.py", line 21, in <module>
    start_date=timezone.datatime(2024, 3, 23),
AttributeError: module 'airflow.utils.timezone' has no attribute 'datatime'
[2024-04-29T18:02:50.615+0000] {processor.py:842} WARNING - No viable dags retrieved from /opt/airflow/dags/my_first_dag.py
[2024-04-29T18:02:50.644+0000] {processor.py:183} INFO - Processing /opt/airflow/dags/my_first_dag.py took 0.048 seconds
[2024-04-29T18:02:58.010+0000] {processor.py:161} INFO - Started process (PID=16894) to work on /opt/airflow/dags/my_first_dag.py
[2024-04-29T18:02:58.011+0000] {processor.py:830} INFO - Processing file /opt/airflow/dags/my_first_dag.py for tasks to queue
[2024-04-29T18:02:58.012+0000] {logging_mixin.py:188} INFO - [2024-04-29T18:02:58.011+0000] {dagbag.py:540} INFO - Filling up the DagBag from /opt/airflow/dags/my_first_dag.py
[2024-04-29T18:02:58.015+0000] {logging_mixin.py:188} INFO - [2024-04-29T18:02:58.014+0000] {dagbag.py:350} ERROR - Failed to import: /opt/airflow/dags/my_first_dag.py
Traceback (most recent call last):
  File "/home/airflow/.local/lib/python3.8/site-packages/airflow/models/dagbag.py", line 346, in parse
    loader.exec_module(new_module)
  File "<frozen importlib._bootstrap_external>", line 843, in exec_module
  File "<frozen importlib._bootstrap>", line 219, in _call_with_frames_removed
  File "/opt/airflow/dags/my_first_dag.py", line 21, in <module>
    start_date=timezone.datatime(2024, 3, 23),
AttributeError: module 'airflow.utils.timezone' has no attribute 'datatime'
[2024-04-29T18:02:58.015+0000] {processor.py:842} WARNING - No viable dags retrieved from /opt/airflow/dags/my_first_dag.py
[2024-04-29T18:02:58.037+0000] {processor.py:183} INFO - Processing /opt/airflow/dags/my_first_dag.py took 0.030 seconds
[2024-04-29T18:03:06.030+0000] {processor.py:161} INFO - Started process (PID=16954) to work on /opt/airflow/dags/my_first_dag.py
[2024-04-29T18:03:06.031+0000] {processor.py:830} INFO - Processing file /opt/airflow/dags/my_first_dag.py for tasks to queue
[2024-04-29T18:03:06.032+0000] {logging_mixin.py:188} INFO - [2024-04-29T18:03:06.031+0000] {dagbag.py:540} INFO - Filling up the DagBag from /opt/airflow/dags/my_first_dag.py
[2024-04-29T18:03:06.036+0000] {logging_mixin.py:188} INFO - [2024-04-29T18:03:06.035+0000] {dagbag.py:350} ERROR - Failed to import: /opt/airflow/dags/my_first_dag.py
Traceback (most recent call last):
  File "/home/airflow/.local/lib/python3.8/site-packages/airflow/models/dagbag.py", line 346, in parse
    loader.exec_module(new_module)
  File "<frozen importlib._bootstrap_external>", line 843, in exec_module
  File "<frozen importlib._bootstrap>", line 219, in _call_with_frames_removed
  File "/opt/airflow/dags/my_first_dag.py", line 21, in <module>
    start_date=timezone.datatime(2024, 3, 23),
AttributeError: module 'airflow.utils.timezone' has no attribute 'datatime'
[2024-04-29T18:03:06.036+0000] {processor.py:842} WARNING - No viable dags retrieved from /opt/airflow/dags/my_first_dag.py
[2024-04-29T18:03:06.064+0000] {processor.py:183} INFO - Processing /opt/airflow/dags/my_first_dag.py took 0.037 seconds
[2024-04-29T18:03:21.335+0000] {processor.py:161} INFO - Started process (PID=17152) to work on /opt/airflow/dags/my_first_dag.py
[2024-04-29T18:03:21.336+0000] {processor.py:830} INFO - Processing file /opt/airflow/dags/my_first_dag.py for tasks to queue
[2024-04-29T18:03:21.337+0000] {logging_mixin.py:188} INFO - [2024-04-29T18:03:21.337+0000] {dagbag.py:540} INFO - Filling up the DagBag from /opt/airflow/dags/my_first_dag.py
[2024-04-29T18:03:21.340+0000] {logging_mixin.py:188} INFO - [2024-04-29T18:03:21.339+0000] {dagbag.py:350} ERROR - Failed to import: /opt/airflow/dags/my_first_dag.py
Traceback (most recent call last):
  File "/home/airflow/.local/lib/python3.8/site-packages/airflow/models/dagbag.py", line 346, in parse
    loader.exec_module(new_module)
  File "<frozen importlib._bootstrap_external>", line 843, in exec_module
  File "<frozen importlib._bootstrap>", line 219, in _call_with_frames_removed
  File "/opt/airflow/dags/my_first_dag.py", line 21, in <module>
    start_date=timezone.datatime(2024, 3, 23),
AttributeError: module 'airflow.utils.timezone' has no attribute 'datatime'
[2024-04-29T18:03:21.340+0000] {processor.py:842} WARNING - No viable dags retrieved from /opt/airflow/dags/my_first_dag.py
[2024-04-29T18:03:21.362+0000] {processor.py:183} INFO - Processing /opt/airflow/dags/my_first_dag.py took 0.029 seconds
[2024-04-29T18:03:23.349+0000] {processor.py:161} INFO - Started process (PID=17157) to work on /opt/airflow/dags/my_first_dag.py
[2024-04-29T18:03:23.350+0000] {processor.py:830} INFO - Processing file /opt/airflow/dags/my_first_dag.py for tasks to queue
[2024-04-29T18:03:23.351+0000] {logging_mixin.py:188} INFO - [2024-04-29T18:03:23.351+0000] {dagbag.py:540} INFO - Filling up the DagBag from /opt/airflow/dags/my_first_dag.py
[2024-04-29T18:03:23.356+0000] {logging_mixin.py:188} INFO - [2024-04-29T18:03:23.355+0000] {dagbag.py:350} ERROR - Failed to import: /opt/airflow/dags/my_first_dag.py
Traceback (most recent call last):
  File "/home/airflow/.local/lib/python3.8/site-packages/airflow/models/dagbag.py", line 346, in parse
    loader.exec_module(new_module)
  File "<frozen importlib._bootstrap_external>", line 843, in exec_module
  File "<frozen importlib._bootstrap>", line 219, in _call_with_frames_removed
  File "/opt/airflow/dags/my_first_dag.py", line 21, in <module>
    start_date=timezone.datatime(2024, 3, 23),
AttributeError: module 'airflow.utils.timezone' has no attribute 'datatime'
[2024-04-29T18:03:23.357+0000] {processor.py:842} WARNING - No viable dags retrieved from /opt/airflow/dags/my_first_dag.py
[2024-04-29T18:03:23.380+0000] {processor.py:183} INFO - Processing /opt/airflow/dags/my_first_dag.py took 0.034 seconds
